Workbook

Sheet CZYTAJ
A1: ETERNAL 13.1 — PROJEKTY, ETAPY I TO, CO MOŻE ZBUDOWAĆ AI
A2: Stan na | B2: 15.10.2026
A3: Źródła | B3: Macierz v11 (arkusze 13 projekty, 35 komponenty, 44 etapy produktów, 45 etapy modułów, 50 roadmapa, 52 karty komponentów); kod Eternal Lite (stan modułów).
A4: Do czego służy | B4: Dla każdego projektu P1–P7: moduły produktowe na etapach MVP, MLP i FINAL, ich funkcjonalności, komponenty użyte do wykonania oraz podział pracy: co napisze AI, a co wymaga ludzi, partnerów, umów lub dopuszczenia.
A5: Etap | B5: MVP, MLP i FINAL to etapy rozwoju danego produktu (arkusz 45), nie daty. Kolumna „Termin wg roadmapy” podaje półrocze startu etapu dla toru z arkusza 50.
A6: Klasy pracy AI
A7: Klasa A | B7: AI buduje całość: własny kod, bez zewnętrznych dostawców
A8: Klasa B | B8: AI buduje całość; człowiek wybiera dostawców, zakłada konta, podpisuje umowy lub licencje
A9: Klasa C | B9: AI buduje oprogramowanie; sprzęt, personel lub usługę fizyczną dostarcza partner
A10: Klasa D | B10: AI buduje kod; wynik regulowany wymaga walidacji klinicznej i dopuszczenia
A11: Klasa E | B11: program badawczy bez gotowego wykonawcy; AI tylko analiza i prototyp programowy
A12: Jak liczona klasa | B12: Szacunek, nie ustalenie. Każdy komponent z zestawu wykonawczego (arkusz 45) dostaje klasę według kolumny „Model wykonania” z arkusza 35: WŁASNY → AI pisze kod; USŁUGA / API / SDK / LICENCJA → adapter plus konto lub umowa; HW i SVC → partner; AI07, AI10, SVC02 → regulowane; RND01, HW10, HW13, HW14 → R&D. Klasa modułu to najtrudniejsza klasa jego komponentów (E > D > C > B > A).
A13: Komponenty kontrolne | B13: Warstwa kontroli (zgody, uprawnienia, audyt, kierowanie do dostawców; arkusz 45 kolumna „Komponenty zabezpieczające”) jest wspólna dla wszystkich modułów, w większości własna (klasa A) i nie zmienia klasy modułu. CTL11 i CTL12 to procesy prowadzone przez ludzi.
A14: Stan w Eternal Lite | B14: Ocena zakresu MVP modułu względem kodu aplikacji z gałęzi ccr-436ad650-eg2hjx. „—” w wierszach MLP i FINAL: etap jeszcze nie zaczęty.
A15: Rozbieżność w źródłach | B15: Arkusze 44 i 45 przypisują Innovation Hub, Forge Marketplace i Eternal Compatible do P5 Matrix; arkusze 13 i 14 — do P6 Hub i P7 Forge. Tu przyjęto podział z arkuszy 13 i 14.
A16: Arkusze | B16: PODSUMOWANIE — projekty i liczby modułów w klasach (formuły); P1…P7 — moduły na etapach; KOLEJKA_AI — co AI może budować najpierw; PRODUKTY_ETAPY — produkty i mikroprodukty na etapach (arkusz 44); KOMPONENTY — 137 komponentów z klasą pracy AI.
A17: Czego AI nie zrobi w żadnym projekcie | B17: Nie podpisze umów, nie założy kont u dostawców, nie przeprowadzi walidacji klinicznej ani certyfikacji, nie wyprodukuje sprzętu, nie zbierze nagrań i wyników do zbiorów testowych, nie zastąpi lekarza ani prawnika.

Sheet PODSUMOWANIE
A1: Podsumowanie: projekty, etapy i klasy pracy AI
A3: Projekt | B3: Czym jest | C3: Co może zbudować AI | D3: Czego AI nie zrobi
A4: P1 Eternal App (oprogramowanie) | B4: Globalna aplikacja i oprogramowanie: App Core, Doctor / Clinic OS, Labs, Medication, Care Access, Wellness, Mental Health, Genetics, Pet, Women & Family, Senior & Rehab, Insurance, Employer, Research / API, Clinical Intelligence. | C4: Prawie całe oprogramowanie: aplikację pacjenta i panel kliniki, rdzeń danych, zgody, OCR i parser, Scribe, rezerwacje, leki, cele i plany, raporty, adaptery do dostawców. | D4: Konta i umowy z dostawcami (OCR, mowa, model, SMS, wideo), partnerów usług (laboratoria, lekarze, apteki), walidację i dopuszczenie dodatków MED, integrację z P1 przez uprawniony podmiot.
A5: P2 Eternal Station | B5: Domowe centrum: bramka urządzeń, monitoring zdalny, dozownik, Care Pod, diagnostyka domowa, stacja dla seniora. | C5: Oprogramowanie bramki i aplikacji, rejestr urządzeń, przebiegi monitoringu i eskalacji do zespołu opieki, integracje z API producentów. | D5: Sprzęt (OEM), certyfikowane urządzenia pomiarowe, personel kliniczny, serwis, obudowy, Care Pod.
A6: P3 Eternal Capsule | B6: Warstwa wewnątrzustrojowa: brama dla implantów i kapsułek, Bio-Tag, monitoring biomarkerów, interfejs neuro, terapie celowane. | C6: Protokół i rejestr urządzeń, ścieżki danych, oprogramowanie integrujące urządzenia partnerów, symulacje i demonstratory badawcze. | D6: Urządzenia i implanty, badania kliniczne, dopuszczenie, programy R&D bez gotowego wykonawcy.
A7: P4 Eternal Digital Twin | B7: Profil podłużny i bliźniak: Digital Shadow, Twin Insights, modele chorób, bliźniak kliniczny, dziedzictwo, bliźniak populacyjny. | C7: Profil podłużny, korelacje opisowe i scenariusze, sejf dziedzictwa, rejestr modeli, środowisko badawcze. | D7: Lata danych, walidację modeli, partnerów naukowych (CRO, uczelnie), dopuszczenie bliźniaka klinicznego.
A8: P5 Eternal Matrix | B8: Społeczność i XR: Matrix Community, Immersive, Therapy / Presence. | C8: Forum z moderacją, wyzwania, edukację, wizualizacje 3D i XR na SDK. | D8: Moderację treści przez ludzi, partnerów terapii, sprzęt XR, personel kliniczny dla terapii.
A9: P6 Hub Innowatora | B9: Hub Innowatora: nabór, ocena, mentoring, granty i konsorcja. | C9: Całe oprogramowanie: nabór, oceny, przebieg grantów, repozytorium dokumentów. | D9: Mentorów, decyzje grantowe, umowy z partnerami.
A10: P7 Eternal Forge | B10: Forge i Eternal Compatible: rejestr technologii, marketplace dostawców i modeli, test zgodności technicznej. | C10: Rejestr i marketplace, katalog dostawców, zestaw testów zgodności adapterów, raporty. | D10: Umowy licencyjne, due diligence, decyzje o certyfikacji (zgodność techniczna, nie medyczna).
A12: Liczba konfiguracji modułów w klasach pracy AI (formuły z arkuszy P1…P7)
A13: Projekt | B13: Etap | C13: A | D13: B | E13: C | F13: D | G13: E | H13: Razem | I13: A+B: AI buduje całość (udział)
A14: P1 Eternal App (oprogramowanie) | B14: MVP | C14: =COUNTIFS(P1_APLIKACJA!$D:$D,$B14,P1_APLIKACJA!$L:$L,"A") -> 27 | D14: =COUNTIFS(P1_APLIKACJA!$D:$D,$B14,P1_APLIKACJA!$L:$L,"B") -> 12 | E14: =COUNTIFS(P1_APLIKACJA!$D:$D,$B14,P1_APLIKACJA!$L:$L,"C") -> 3 | F14: =COUNTIFS(P1_APLIKACJA!$D:$D,$B14,P1_APLIKACJA!$L:$L,"D") -> 0 | G14: =COUNTIFS(P1_APLIKACJA!$D:$D,$B14,P1_APLIKACJA!$L:$L,"E") -> 0 | H14: =SUM(C14:G14) -> 42 | I14: =IF(H14=0,"-",(C14+D14)/H14) -> 0.92857143
A15: P1 Eternal App (oprogramowanie) | B15: MLP | C15: =COUNTIFS(P1_APLIKACJA!$D:$D,$B15,P1_APLIKACJA!$L:$L,"A") -> 11 | D15: =COUNTIFS(P1_APLIKACJA!$D:$D,$B15,P1_APLIKACJA!$L:$L,"B") -> 15 | E15: =COUNTIFS(P1_APLIKACJA!$D:$D,$B15,P1_APLIKACJA!$L:$L,"C") -> 11 | F15: =COUNTIFS(P1_APLIKACJA!$D:$D,$B15,P1_APLIKACJA!$L:$L,"D") -> 5 | G15: =COUNTIFS(P1_APLIKACJA!$D:$D,$B15,P1_APLIKACJA!$L:$L,"E") -> 0 | H15: =SUM(C15:G15) -> 42 | I15: =IF(H15=0,"-",(C15+D15)/H15) -> 0.61904762
A16: P1 Eternal App (oprogramowanie) | B16: FINAL | C16: =COUNTIFS(P1_APLIKACJA!$D:$D,$B16,P1_APLIKACJA!$L:$L,"A") -> 4 | D16: =COUNTIFS(P1_APLIKACJA!$D:$D,$B16,P1_APLIKACJA!$L:$L,"B") -> 15 | E16: =COUNTIFS(P1_APLIKACJA!$D:$D,$B16,P1_APLIKACJA!$L:$L,"C") -> 15 | F16: =COUNTIFS(P1_APLIKACJA!$D:$D,$B16,P1_APLIKACJA!$L:$L,"D") -> 8 | G16: =COUNTIFS(P1_APLIKACJA!$D:$D,$B16,P1_APLIKACJA!$L:$L,"E") -> 0 | H16: =SUM(C16:G16) -> 42 | I16: =IF(H16=0,"-",(C16+D16)/H16) -> 0.45238095
A17: P2 Eternal Station | B17: MVP | C17: =COUNTIFS(P2_STATION!$D:$D,$B17,P2_STATION!$L:$L,"A") -> 2 | D17: =COUNTIFS(P2_STATION!$D:$D,$B17,P2_STATION!$L:$L,"B") -> 0 | E17: =COUNTIFS(P2_STATION!$D:$D,$B17,P2_STATION!$L:$L,"C") -> 5 | F17: =COUNTIFS(P2_STATION!$D:$D,$B17,P2_STATION!$L:$L,"D") -> 0 | G17: =COUNTIFS(P2_STATION!$D:$D,$B17,P2_STATION!$L:$L,"E") -> 0 | H17: =SUM(C17:G17) -> 7 | I17: =IF(H17=0,"-",(C17+D17)/H17) -> 0.28571429
A18: P2 Eternal Station | B18: MLP | C18: =COUNTIFS(P2_STATION!$D:$D,$B18,P2_STATION!$L:$L,"A") -> 0 | D18: =COUNTIFS(P2_STATION!$D:$D,$B18,P2_STATION!$L:$L,"B") -> 0 | E18: =COUNTIFS(P2_STATION!$D:$D,$B18,P2_STATION!$L:$L,"C") -> 7 | F18: =COUNTIFS(P2_STATION!$D:$D,$B18,P2_STATION!$L:$L,"D") -> 0 | G18: =COUNTIFS(P2_STATION!$D:$D,$B18,P2_STATION!$L:$L,"E") -> 0 | H18: =SUM(C18:G18) -> 7 | I18: =IF(H18=0,"-",(C18+D18)/H18) -> 0
A19: P2 Eternal Station | B19: FINAL | C19: =COUNTIFS(P2_STATION!$D:$D,$B19,P2_STATION!$L:$L,"A") -> 0 | D19: =COUNTIFS(P2_STATION!$D:$D,$B19,P2_STATION!$L:$L,"B") -> 0 | E19: =COUNTIFS(P2_STATION!$D:$D,$B19,P2_STATION!$L:$L,"C") -> 7 | F19: =COUNTIFS(P2_STATION!$D:$D,$B19,P2_STATION!$L:$L,"D") -> 0 | G19: =COUNTIFS(P2_STATION!$D:$D,$B19,P2_STATION!$L:$L,"E") -> 0 | H19: =SUM(C19:G19) -> 7 | I19: =IF(H19=0,"-",(C19+D19)/H19) -> 0
A20: P3 Eternal Capsule | B20: MVP | C20: =COUNTIFS(P3_CAPSULE!$D:$D,$B20,P3_CAPSULE!$L:$L,"A") -> 1 | D20: =COUNTIFS(P3_CAPSULE!$D:$D,$B20,P3_CAPSULE!$L:$L,"B") -> 2 | E20: =COUNTIFS(P3_CAPSULE!$D:$D,$B20,P3_CAPSULE!$L:$L,"C") -> 3 | F20: =COUNTIFS(P3_CAPSULE!$D:$D,$B20,P3_CAPSULE!$L:$L,"D") -> 0 | G20: =COUNTIFS(P3_CAPSULE!$D:$D,$B20,P3_CAPSULE!$L:$L,"E") -> 0 | H20: =SUM(C20:G20) -> 6 | I20: =IF(H20=0,"-",(C20+D20)/H20) -> 0.5
A21: P3 Eternal Capsule | B21: MLP | C21: =COUNTIFS(P3_CAPSULE!$D:$D,$B21,P3_CAPSULE!$L:$L,"A") -> 0 | D21: =COUNTIFS(P3_CAPSULE!$D:$D,$B21,P3_CAPSULE!$L:$L,"B") -> 0 | E21: =COUNTIFS(P3_CAPSULE!$D:$D,$B21,P3_CAPSULE!$L:$L,"C") -> 5 | F21: =COUNTIFS(P3_CAPSULE!$D:$D,$B21,P3_CAPSULE!$L:$L,"D") -> 0 | G21: =COUNTIFS(P3_CAPSULE!$D:$D,$B21,P3_CAPSULE!$L:$L,"E") -> 1 | H21: =SUM(C21:G21) -> 6 | I21: =IF(H21=0,"-",(C21+D21)/H21) -> 0
A22: P3 Eternal Capsule | B22: FINAL | C22: =COUNTIFS(P3_CAPSULE!$D:$D,$B22,P3_CAPSULE!$L:$L,"A") -> 0 | D22: =COUNTIFS(P3_CAPSULE!$D:$D,$B22,P3_CAPSULE!$L:$L,"B") -> 0 | E22: =COUNTIFS(P3_CAPSULE!$D:$D,$B22,P3_CAPSULE!$L:$L,"C") -> 3 | F22: =COUNTIFS(P3_CAPSULE!$D:$D,$B22,P3_CAPSULE!$L:$L,"D") -> 0 | G22: =COUNTIFS(P3_CAPSULE!$D:$D,$B22,P3_CAPSULE!$L:$L,"E") -> 3 | H22: =SUM(C22:G22) -> 6 | I22: =IF(H22=0,"-",(C22+D22)/H22) -> 0
A23: P4 Eternal Digital Twin | B23: MVP | C23: =COUNTIFS(P4_DIGITAL_TWIN!$D:$D,$B23,P4_DIGITAL_TWIN!$L:$L,"A") -> 2 | D23: =COUNTIFS(P4_DIGITAL_TWIN!$D:$D,$B23,P4_DIGITAL_TWIN!$L:$L,"B") -> 2 | E23: =COUNTIFS(P4_DIGITAL_TWIN!$D:$D,$B23,P4_DIGITAL_TWIN!$L:$L,"C") -> 2 | F23: =COUNTIFS(P4_DIGITAL_TWIN!$D:$D,$B23,P4_DIGITAL_TWIN!$L:$L,"D") -> 0 | G23: =COUNTIFS(P4_DIGITAL_TWIN!$D:$D,$B23,P4_DIGITAL_TWIN!$L:$L,"E") -> 0 | H23: =SUM(C23:G23) -> 6 | I23: =IF(H23=0,"-",(C23+D23)/H23) -> 0.66666667
A24: P4 Eternal Digital Twin | B24: MLP | C24: =COUNTIFS(P4_DIGITAL_TWIN!$D:$D,$B24,P4_DIGITAL_TWIN!$L:$L,"A") -> 1 | D24: =COUNTIFS(P4_DIGITAL_TWIN!$D:$D,$B24,P4_DIGITAL_TWIN!$L:$L,"B") -> 2 | E24: =COUNTIFS(P4_DIGITAL_TWIN!$D:$D,$B24,P4_DIGITAL_TWIN!$L:$L,"C") -> 2 | F24: =COUNTIFS(P4_DIGITAL_TWIN!$D:$D,$B24,P4_DIGITAL_TWIN!$L:$L,"D") -> 1 | G24: =COUNTIFS(P4_DIGITAL_TWIN!$D:$D,$B24,P4_DIGITAL_TWIN!$L:$L,"E") -> 0 | H24: =SUM(C24:G24) -> 6 | I24: =IF(H24=0,"-",(C24+D24)/H24) -> 0.5
A25: P4 Eternal Digital Twin | B25: FINAL | C25: =COUNTIFS(P4_DIGITAL_TWIN!$D:$D,$B25,P4_DIGITAL_TWIN!$L:$L,"A") -> 1 | D25: =COUNTIFS(P4_DIGITAL_TWIN!$D:$D,$B25,P4_DIGITAL_TWIN!$L:$L,"B") -> 2 | E25: =COUNTIFS(P4_DIGITAL_TWIN!$D:$D,$B25,P4_DIGITAL_TWIN!$L:$L,"C") -> 1 | F25: =COUNTIFS(P4_DIGITAL_TWIN!$D:$D,$B25,P4_DIGITAL_TWIN!$L:$L,"D") -> 2 | G25: =COUNTIFS(P4_DIGITAL_TWIN!$D:$D,$B25,P4_DIGITAL_TWIN!$L:$L,"E") -> 0 | H25: =SUM(C25:G25) -> 6 | I25: =IF(H25=0,"-",(C25+D25)/H25) -> 0.5
A26: P5 Eternal Matrix | B26: MVP | C26: =COUNTIFS(P5_MATRIX!$D:$D,$B26,P5_MATRIX!$L:$L,"A") -> 2 | D26: =COUNTIFS(P5_MATRIX!$D:$D,$B26,P5_MATRIX!$L:$L,"B") -> 0 | E26: =COUNTIFS(P5_MATRIX!$D:$D,$B26,P5_MATRIX!$L:$L,"C") -> 1 | F26: =COUNTIFS(P5_MATRIX!$D:$D,$B26,P5_MATRIX!$L:$L,"D") -> 0 | G26: =COUNTIFS(P5_MATRIX!$D:$D,$B26,P5_MATRIX!$L:$L,"E") -> 0 | H26: =SUM(C26:G26) -> 3 | I26: =IF(H26=0,"-",(C26+D26)/H26) -> 0.66666667
A27: P5 Eternal Matrix | B27: MLP | C27: =COUNTIFS(P5_MATRIX!$D:$D,$B27,P5_MATRIX!$L:$L,"A") -> 1 | D27: =COUNTIFS(P5_MATRIX!$D:$D,$B27,P5_MATRIX!$L:$L,"B") -> 1 | E27: =COUNTIFS(P5_MATRIX!$D:$D,$B27,P5_MATRIX!$L:$L,"C") -> 1 | F27: =COUNTIFS(P5_MATRIX!$D:$D,$B27,P5_MATRIX!$L:$L,"D") -> 0 | G27: =COUNTIFS(P5_MATRIX!$D:$D,$B27,P5_MATRIX!$L:$L,"E") -> 0 | H27: =SUM(C27:G27) -> 3 | I27: =IF(H27=0,"-",(C27+D27)/H27) -> 0.66666667
A28: P5 Eternal Matrix | B28: FINAL | C28: =COUNTIFS(P5_MATRIX!$D:$D,$B28,P5_MATRIX!$L:$L,"A") -> 1 | D28: =COUNTIFS(P5_MATRIX!$D:$D,$B28,P5_MATRIX!$L:$L,"B") -> 1 | E28: =COUNTIFS(P5_MATRIX!$D:$D,$B28,P5_MATRIX!$L:$L,"C") -> 1 | F28: =COUNTIFS(P5_MATRIX!$D:$D,$B28,P5_MATRIX!$L:$L,"D") -> 0 | G28: =COUNTIFS(P5_MATRIX!$D:$D,$B28,P5_MATRIX!$L:$L,"E") -> 0 | H28: =SUM(C28:G28) -> 3 | I28: =IF(H28=0,"-",(C28+D28)/H28) -> 0.66666667
A29: P6 Hub Innowatora | B29: MVP | C29: =COUNTIFS(P6_HUB!$D:$D,$B29,P6_HUB!$L:$L,"A") -> 1 | D29: =COUNTIFS(P6_HUB!$D:$D,$B29,P6_HUB!$L:$L,"B") -> 1 | E29: =COUNTIFS(P6_HUB!$D:$D,$B29,P6_HUB!$L:$L,"C") -> 0 | F29: =COUNTIFS(P6_HUB!$D:$D,$B29,P6_HUB!$L:$L,"D") -> 0 | G29: =COUNTIFS(P6_HUB!$D:$D,$B29,P6_HUB!$L:$L,"E") -> 0 | H29: =SUM(C29:G29) -> 2 | I29: =IF(H29=0,"-",(C29+D29)/H29) -> 1
A30: P6 Hub Innowatora | B30: MLP | C30: =COUNTIFS(P6_HUB!$D:$D,$B30,P6_HUB!$L:$L,"A") -> 0 | D30: =COUNTIFS(P6_HUB!$D:$D,$B30,P6_HUB!$L:$L,"B") -> 2 | E30: =COUNTIFS(P6_HUB!$D:$D,$B30,P6_HUB!$L:$L,"C") -> 0 | F30: =COUNTIFS(P6_HUB!$D:$D,$B30,P6_HUB!$L:$L,"D") -> 0 | G30: =COUNTIFS(P6_HUB!$D:$D,$B30,P6_HUB!$L:$L,"E") -> 0 | H30: =SUM(C30:G30) -> 2 | I30: =IF(H30=0,"-",(C30+D30)/H30) -> 1
A31: P6 Hub Innowatora | B31: FINAL | C31: =COUNTIFS(P6_HUB!$D:$D,$B31,P6_HUB!$L:$L,"A") -> 0 | D31: =COUNTIFS(P6_HUB!$D:$D,$B31,P6_HUB!$L:$L,"B") -> 1 | E31: =COUNTIFS(P6_HUB!$D:$D,$B31,P6_HUB!$L:$L,"C") -> 1 | F31: =COUNTIFS(P6_HUB!$D:$D,$B31,P6_HUB!$L:$L,"D") -> 0 | G31: =COUNTIFS(P6_HUB!$D:$D,$B31,P6_HUB!$L:$L,"E") -> 0 | H31: =SUM(C31:G31) -> 2 | I31: =IF(H31=0,"-",(C31+D31)/H31) -> 0.5
A32: P7 Eternal Forge | B32: MVP | C32: =COUNTIFS(P7_FORGE!$D:$D,$B32,P7_FORGE!$L:$L,"A") -> 3 | D32: =COUNTIFS(P7_FORGE!$D:$D,$B32,P7_FORGE!$L:$L,"B") -> 0 | E32: =COUNTIFS(P7_FORGE!$D:$D,$B32,P7_FORGE!$L:$L,"C") -> 0 | F32: =COUNTIFS(P7_FORGE!$D:$D,$B32,P7_FORGE!$L:$L,"D") -> 0 | G32: =COUNTIFS(P7_FORGE!$D:$D,$B32,P7_FORGE!$L:$L,"E") -> 0 | H32: =SUM(C32:G32) -> 3 | I32: =IF(H32=0,"-",(C32+D32)/H32) -> 1
A33: P7 Eternal Forge | B33: MLP | C33: =COUNTIFS(P7_FORGE!$D:$D,$B33,P7_FORGE!$L:$L,"A") -> 1 | D33: =COUNTIFS(P7_FORGE!$D:$D,$B33,P7_FORGE!$L:$L,"B") -> 2 | E33: =COUNTIFS(P7_FORGE!$D:$D,$B33,P7_FORGE!$L:$L,"C") -> 0 | F33: =COUNTIFS(P7_FORGE!$D:$D,$B33,P7_FORGE!$L:$L,"D") -> 0 | G33: =COUNTIFS(P7_FORGE!$D:$D,$B33,P7_FORGE!$L:$L,"E") -> 0 | H33: =SUM(C33:G33) -> 3 | I33: =IF(H33=0,"-",(C33+D33)/H33) -> 1
A34: P7 Eternal Forge | B34: FINAL | C34: =COUNTIFS(P7_FORGE!$D:$D,$B34,P7_FORGE!$L:$L,"A") -> 1 | D34: =COUNTIFS(P7_FORGE!$D:$D,$B34,P7_FORGE!$L:$L,"B") -> 2 | E34: =COUNTIFS(P7_FORGE!$D:$D,$B34,P7_FORGE!$L:$L,"C") -> 0 | F34: =COUNTIFS(P7_FORGE!$D:$D,$B34,P7_FORGE!$L:$L,"D") -> 0 | G34: =COUNTIFS(P7_FORGE!$D:$D,$B34,P7_FORGE!$L:$L,"E") -> 0 | H34: =SUM(C34:G34) -> 3 | I34: =IF(H34=0,"-",(C34+D34)/H34) -> 1
A35: Razem | C35: =SUM(C14:C34) -> 59 | D35: =SUM(D14:D34) -> 60 | E35: =SUM(E14:E34) -> 68 | F35: =SUM(F14:F34) -> 16 | G35: =SUM(G14:G34) -> 4 | H35: =SUM(H14:H34) -> 207 | I35: =IF(H35=0,"-",(C35+D35)/H35) -> 0.57487923
A37: Legenda klas
A38: A | B38: AI buduje całość: własny kod, bez zewnętrznych dostawców
A39: B | B39: AI buduje całość; człowiek wybiera dostawców, zakłada konta, podpisuje umowy lub licencje
A40: C | B40: AI buduje oprogramowanie; sprzęt, personel lub usługę fizyczną dostarcza partner
A41: D | B41: AI buduje kod; wynik regulowany wymaga walidacji klinicznej i dopuszczenia
A42: E | B42: program badawczy bez gotowego wykonawcy; AI tylko analiza i prototyp programowy

Sheet KOLEJKA_AI
A1: Co AI może budować najpierw: moduły MVP klasy A i B, których brakuje lub są częściowe w Eternal Lite
A2: Kolejność: termin z roadmapy, potem projekt i numer modułu. Klasa B wymaga po stronie człowieka konta lub umowy u dostawcy.
A3: Projekt | B3: Moduł ID | C3: Moduł produktowy | D3: Produkt | E3: Termin wg roadmapy | F3: Klasa | G3: Funkcjonalności MVP | H3: Stan w Eternal Lite | I3: Co zrobi AI | J3: Co zrobi człowiek | K3: Uwaga
A4: P1 Eternal App (oprogramowanie) | B4: M03 | C4: Dokumenty i OCR | D4: Eternal App Core | E4: 2026 H2 | F4: B | G4: OCR i korekta użytkownika | H4: częściowo: PDF z tekstem i polski rozbiór wyników; OCR zdjęć gotowy w kodzie, bez konta u dostawcy | I4: Kod: DAT05 Importer i parser dokumentów; DAT03 Pochodzenie danych i wersjonowanie Adaptery i integracje: AI01 OCR Testy automatyczne i dokumentacja techniczna | J4: Wybór dostawcy, konto, umowa powierzenia lub licencja: AI01 OCR Akceptacja zakresu, testy z użytkownikami
A5: P1 Eternal App (oprogramowanie) | B5: M14 | C5: Lab Vault i OCR | D5: Eternal Labs | E5: 2026 H2 | F5: B | G5: Wgrywanie, OCR i historia wyników | H5: częściowo: wyniki z PDF z LOINC/UCUM i źródłem; brak osobnego Lab Vault | I5: Kod: DAT05 Importer i parser dokumentów; DAT03 Pochodzenie danych i wersjonowanie; APP02 Raport i zestawienie Adaptery i integracje: AI01 OCR Testy automatyczne i dokumentacja techniczna | J5: Wybór dostawcy, konto, umowa powierzenia lub licencja: AI01 OCR Akceptacja zakresu, testy z użytkownikami
A6: P1 Eternal App (oprogramowanie) | B6: M16 | C6: Interpretacja wyników laboratoryjnych | D6: Eternal Labs | E6: 2026 H2 | F6: A | G6: Edukacyjne objaśnienie terminów | H6: brak | I6: Kod: AI04 Retriever RAG; APP12 Treści edukacyjne i audio; APP02 Raport i zestawienie Testy automatyczne i dokumentacja techniczna | J6: Akceptacja zakresu, testy z użytkownikami | K6: Objaśnienie terminów ze słownika, bez oceny wyniku (granica wyrobu medycznego).
A7: P1 Eternal App (oprogramowanie) | B7: M27 | C7: Wywiad przed wizytą | D7: Eternal Doctor / Clinic OS | E7: 2026 H2 | F7: A | G7: Formularz przed wizytą | H7: częściowo: ankiety przed wizytą; brak wywiadu z asystentem | I7: Kod: APP04 Formularze i wywiad Testy automatyczne i dokumentacja techniczna | J7: Akceptacja zakresu, testy z użytkownikami
A8: P1 Eternal App (oprogramowanie) | B8: M28 | C8: Integracje szpitalne, FHIR i krajowe | D8: Eternal Doctor / Clinic OS | E8: 2026 H2 | F8: A | G8: Import/eksport plików | H8: częściowo: odczyt FHIR R4, adapter Medplum; brak łączników HIS i P1 | I8: Kod: DAT05 Importer i parser dokumentów; DAT02 Mapper interoperacyjności Testy automatyczne i dokumentacja techniczna | J8: Akceptacja zakresu, testy z użytkownikami
A9: P1 Eternal App (oprogramowanie) | B9: M30 | C9: Personalizacja dla wielu organizacji | D9: Eternal Doctor / Clinic OS | E9: 2026 H2 | F9: A | G9: Role i konfiguracja kliniki | H9: częściowo: organizacje, moduły włączane per klinika, wdrożenie stopniowe; brak pakietów specjalizacji i marki | I9: Kod: CTL04 Izolacja organizacji; CTL02 Silnik uprawnień; APP29 Pakiety i subskrypcje Testy automatyczne i dokumentacja techniczna | J9: Akceptacja zakresu, testy z użytkownikami
A10: P1 Eternal App (oprogramowanie) | B10: M58 | C10: Pet Health Passport | D10: Eternal Pet | E10: 2026 H2 | F10: A | G10: Paszport zwierzęcia i dokumenty | H10: brak | I10: Kod: APP24 Zwierzęta; DAT05 Importer i parser dokumentów Testy automatyczne i dokumentacja techniczna | J10: Akceptacja zakresu, testy z użytkownikami
A11: P1 Eternal App (oprogramowanie) | B11: M59 | C11: Urządzenia dla zwierząt / teleweterynaria | D11: Eternal Pet | E11: 2026 H2 | F11: B | G11: Tracker i katalog lecznic | H11: brak | I11: Kod: APP24 Zwierzęta; APP06 Rezerwacje Adaptery i integracje: INT04 Adapter bezpośredni OEM Testy automatyczne i dokumentacja techniczna | J11: Wybór dostawcy, konto, umowa powierzenia lub licencja: INT04 Adapter bezpośredni OEM Akceptacja zakresu, testy z użytkownikami
A12: P1 Eternal App (oprogramowanie) | B12: M62 | C12: Senior / dostępność / opiekun | D12: Eternal Senior & Rehab | E12: 2026 H2 | F12: A | G12: Dostępny interfejs i opiekun | H12: częściowo: dostępność interfejsu, osoby bliskie w SOS, udostępnienie karty | I12: Kod: APP18 Dostępność; APP17 Rodzina i opiekunowie Testy automatyczne i dokumentacja techniczna | J12: Akceptacja zakresu, testy z użytkownikami
A13: P1 Eternal App (oprogramowanie) | B13: M04 | C13: Universal Sync | D13: Eternal App Core | E13: 2027 H1 | F13: B | G13: Universal Sync: jeden agregator, bez własnego urządzenia noszonego | H13: częściowo: Withings, Bluetooth w przeglądarce, dane z platform monitoringu (webhook); brak Terra, HealthKit, Health Connect | I13: Kod: DAT01 Kanoniczny rekord zdrowia; DAT03 Pochodzenie danych i wersjonowanie; DAT04 Deduplikacja i jakość danych Adaptery i integracje: INT03 Adapter Terra Testy automatyczne i dokumentacja techniczna | J13: Wybór dostawcy, konto, umowa powierzenia lub licencja: INT03 Adapter Terra Akceptacja zakresu, testy z użytkownikami
A14: P1 Eternal App (oprogramowanie) | B14: M18 | C14: Krajowy pomost e-recepty i skierowań | D14: Eternal Medication | E14: 2027 H1 | F14: A | G14: Przechowanie recepty/skierowania | H14: brak: kod e-recepty widoczny w karcie po wizycie, bez pomostu do P1 | I14: Kod: DAT05 Importer i parser dokumentów; APP19 Rejestr leków Testy automatyczne i dokumentacja techniczna | J14: Akceptacja zakresu, testy z użytkownikami | K14: MVP to przechowanie recepty i skierowania; integracja z P1 tylko przez uprawniony podmiot.
A15: P1 Eternal App (oprogramowanie) | B15: M31 | C15: Dodatek Clinical Intelligence | D15: Eternal Clinical Intelligence | E15: 2027 H1 | F15: B | G15: Asystent informacyjny: współdzielony M69 | H15: brak | I15: Kod: AI04 Retriever RAG; AI13 Weryfikator cytowań i odpowiedzi; APP12 Treści edukacyjne i audio Adaptery i integracje: AI03 Model językowy Testy automatyczne i dokumentacja techniczna | J15: Wybór dostawcy, konto, umowa powierzenia lub licencja: AI03 Model językowy Akceptacja zakresu, testy z użytkownikami | K15: MVP wspólny z M69 (asystent informacyjny); każde nowe przeznaczenie wymaga oceny MDR.
A16: P1 Eternal App (oprogramowanie) | B16: M64 | C16: Portfel polis / porównanie | D16: Eternal Insurance / Benefits | E16: 2027 H1 | F16: A | G16: Portfel polis i porównanie | H16: brak | I16: Kod: APP26 Ubezpieczenia i świadczenia; DAT05 Importer i parser dokumentów Testy automatyczne i dokumentacja techniczna | J16: Akceptacja zakresu, testy z użytkownikami
A17: P1 Eternal App (oprogramowanie) | B17: M65 | C17: Ścieżka oceny punktowej / underwritingu | D17: Eternal Insurance / Benefits | E17: 2027 H1 | F17: B | G17: Analiza wykonalności; bez scoringu produkcyjnego | H17: brak | I17: Kod: APP16 Nabór i współpraca R&D Narzędzia i szablony dokumentów dla: CTL11 Brama przeznaczenia i kraju Testy automatyczne i dokumentacja techniczna | J17: Prowadzenie procesu: CTL11 Brama przeznaczenia i kraju Akceptacja zakresu, testy z użytkownikami | K17: Analiza wykonalności bez produkcyjnego scoringu; możliwy STOP.
A18: P1 Eternal App (oprogramowanie) | B18: M66 | C18: Pakiet wellness dla pracodawcy | D18: Eternal Employer / Population Health | E18: 2027 H1 | F18: A | G18: Dobrowolny program wellness | H18: brak | I18: Kod: APP29 Pakiety i subskrypcje; APP11 Cele i plany Testy automatyczne i dokumentacja techniczna | J18: Akceptacja zakresu, testy z użytkownikami
A19: P1 Eternal App (oprogramowanie) | B19: M67 | C19: Zbiorcza analityka programu | D19: Eternal Employer / Population Health | E19: 2027 H1 | F19: A | G19: Raport z bezpiecznych agregatów | H19: brak | I19: Kod: APP27 Analityka programów; DAT09 Kohorty i środowisko badawcze Testy automatyczne i dokumentacja techniczna | J19: Akceptacja zakresu, testy z użytkownikami
A20: P1 Eternal App (oprogramowanie) | B20: M69 | C20: Orkiestracja dowodów i AI | D20: Evidence Assistant | E20: 2027 H1 | F20: B | G20: RAG i cytowanie: edukacja, źródła, odmowa | H20: brak | I20: Kod: AI04 Retriever RAG; AI13 Weryfikator cytowań i odpowiedzi; APP12 Treści edukacyjne i audio Adaptery i integracje: AI03 Model językowy; INF12 Indeks wyszukiwania Testy automatyczne i dokumentacja techniczna | J20: Wybór dostawcy, konto, umowa powierzenia lub licencja: AI03 Model językowy; INF12 Indeks wyszukiwania Akceptacja zakresu, testy z użytkownikami | K20: Odpowiedzi z cytowaniem i jawną odmową; ewaluacja przed każdym wydaniem.
A21: P1 Eternal App (oprogramowanie) | B21: M07 | C21: Sen | D21: Eternal Wellness Composer | E21: 2027 H2 | F21: A | G21: Dziennik snu i edukacja | H21: brak | I21: Kod: APP21 Sen; APP12 Treści edukacyjne i audio Testy automatyczne i dokumentacja techniczna | J21: Akceptacja zakresu, testy z użytkownikami
A22: P1 Eternal App (oprogramowanie) | B22: M08 | C22: Żywienie | D22: Eternal Wellness Composer | E22: 2027 H2 | F22: A | G22: Dziennik posiłków i treści | H22: brak | I22: Kod: APP20 Żywienie; APP12 Treści edukacyjne i audio Testy automatyczne i dokumentacja techniczna | J22: Akceptacja zakresu, testy z użytkownikami
A23: P1 Eternal App (oprogramowanie) | B23: M09 | C23: Fitness | D23: Eternal Wellness Composer | E23: 2027 H2 | F23: A | G23: Aktywność i plan ogólny | H23: brak | I23: Kod: APP22 Ruch i trening; APP11 Cele i plany Testy automatyczne i dokumentacja techniczna | J23: Akceptacja zakresu, testy z użytkownikami
A24: P1 Eternal App (oprogramowanie) | B24: M10 | C24: Środowisko / bio-pogoda | D24: Eternal Wellness Composer | E24: 2027 H2 | F24: B | G24: Pogoda i środowisko | H24: brak | I24: Kod: APP12 Treści edukacyjne i audio Adaptery i integracje: INT15 Dane środowiskowe Testy automatyczne i dokumentacja techniczna | J24: Wybór dostawcy, konto, umowa powierzenia lub licencja: INT15 Dane środowiskowe Akceptacja zakresu, testy z użytkownikami
A25: P1 Eternal App (oprogramowanie) | B25: M11 | C25: Długowieczność | D25: Eternal Wellness Composer | E25: 2027 H2 | F25: A | G25: Trendy i edukacja profilaktyczna | H25: brak | I25: Kod: DAT07 Widok podłużny; APP10 Trendy i wskaźniki; APP12 Treści edukacyjne i audio Testy automatyczne i dokumentacja techniczna | J25: Akceptacja zakresu, testy z użytkownikami
A26: P5 Eternal Matrix | B26: M50 | C26: Społeczność / wyzwania / edukacja | D26: Matrix Community | E26: 2028 H1 | F26: A | G26: Treści i moderowana grupa | H26: brak | I26: Kod: APP12 Treści edukacyjne i audio; APP13 Społeczność Testy automatyczne i dokumentacja techniczna | J26: Akceptacja zakresu, testy z użytkownikami
A27: P5 Eternal Matrix | B27: M51 | C27: Przestrzenie zdrowia AR/VR | D27: Matrix Immersive | E27: 2028 H1 | F27: A | G27: Wizualizacja w przeglądarce | H27: brak | I27: Kod: APP14 Wizualizacja 3D/XR; APP12 Treści edukacyjne i audio Testy automatyczne i dokumentacja techniczna | J27: Akceptacja zakresu, testy z użytkownikami
A28: P6 Hub Innowatora | B28: M53 | C28: Wyszukiwanie / ocena / mentoring | D28: Innovation Hub | E28: 2028 H1 | F28: A | G28: Formularz zgłoszenia i ręczna ocena | H28: brak | I28: Kod: APP04 Formularze i wywiad; APP16 Nabór i współpraca R&D Testy automatyczne i dokumentacja techniczna | J28: Akceptacja zakresu, testy z użytkownikami
A29: P6 Hub Innowatora | B29: M54 | C29: Kreator grantów i konsorcjów | D29: Innovation Hub | E29: 2028 H1 | F29: B | G29: Rejestr konkursów i dokumentacja | H29: brak | I29: Kod: APP16 Nabór i współpraca R&D Adaptery i integracje: INF03 Magazyn plików Testy automatyczne i dokumentacja techniczna | J29: Wybór dostawcy, konto, umowa powierzenia lub licencja: INF03 Magazyn plików Akceptacja zakresu, testy z użytkownikami
A30: P7 Eternal Forge | B30: M55 | C30: Rejestr i marketplace technologii | D30: Forge Marketplace | E30: 2028 H1 | F30: A | G30: Katalog i ręczne due diligence | H30: brak | I30: Kod: APP15 Katalog technologii; CTL05 Katalog dostawców Testy automatyczne i dokumentacja techniczna | J30: Akceptacja zakresu, testy z użytkownikami
A31: P7 Eternal Forge | B31: M56 | C31: Certyfikacja zgodności | D31: Eternal Compatible | E31: 2028 H1 | F31: A | G31: Specyfikacja i ręczny test adaptera | H31: brak | I31: Kod: CTL07 Fabryka adapterów; CTL20 Rejestr funkcji Testy automatyczne i dokumentacja techniczna | J31: Akceptacja zakresu, testy z użytkownikami
A32: P7 Eternal Forge | B32: M57 | C32: Marketplace dostawców i modeli | D32: Forge Marketplace | E32: 2028 H1 | F32: A | G32: Rejestr wykonawców i wybór ręczny | H32: brak | I32: Kod: CTL05 Katalog dostawców; APP15 Katalog technologii Testy automatyczne i dokumentacja techniczna | J32: Akceptacja zakresu, testy z użytkownikami
A33: P1 Eternal App (oprogramowanie) | B33: M12 | C33: Marketplace świadczeniodawców i rezerwacje | D33: Eternal Care Access | E33: nie ma toru w roadmapie | F33: A | G33: Katalog i przekierowanie do partnera | H33: częściowo: rezerwacja w placówce; brak katalogu wielu świadczeniodawców | I33: Kod: APP06 Rezerwacje; APP15 Katalog technologii Testy automatyczne i dokumentacja techniczna | J33: Akceptacja zakresu, testy z użytkownikami
A34: P1 Eternal App (oprogramowanie) | B34: M19 | C34: Dobrostan i dostęp w kryzysie | D34: Eternal Mental Health | E34: nie ma toru w roadmapie | F34: A | G34: Dziennik, edukacja i pomoc kryzysowa | H34: częściowo: numery 112 i 116 123 zawsze widoczne, SOS; brak treści dobrostanu | I34: Kod: APP12 Treści edukacyjne i audio; APP28 Ścieżka pomocy kryzysowej; APP04 Formularze i wywiad Testy automatyczne i dokumentacja techniczna | J34: Akceptacja zakresu, testy z użytkownikami | K34: Pomoc kryzysowa zawsze bezpłatna.
A35: P1 Eternal App (oprogramowanie) | B35: M21 | C35: Sejf genetyczny / dostęp do badań | D35: Eternal Genetics | E35: nie ma toru w roadmapie | F35: A | G35: Sejf genetyczny: import raportu | H35: brak | I35: Kod: APP23 Dane genetyczne; DAT05 Importer i parser dokumentów; DAT03 Pochodzenie danych i wersjonowanie Testy automatyczne i dokumentacja techniczna | J35: Akceptacja zakresu, testy z użytkownikami
A36: P1 Eternal App (oprogramowanie) | B36: M22 | C36: Interpretacja genetyczna i farmakogenomiczna | D36: Eternal Genetics | E36: nie ma toru w roadmapie | F36: A | G36: Edukacja terminów genetycznych | H36: brak | I36: Kod: APP12 Treści edukacyjne i audio; APP23 Dane genetyczne Testy automatyczne i dokumentacja techniczna | J36: Akceptacja zakresu, testy z użytkownikami
A37: P1 Eternal App (oprogramowanie) | B37: M60 | C37: Kobiety / płodność / ciąża | D37: Eternal Women & Family | E37: brak osobnego toru; w torze rodziny MVP 2026 H2 to tylko dostępność | F37: A | G37: Dziennik cyklu/ciąży i edukacja | H37: brak | I37: Kod: APP04 Formularze i wywiad; APP12 Treści edukacyjne i audio; APP09 Przypomnienia Testy automatyczne i dokumentacja techniczna | J37: Akceptacja zakresu, testy z użytkownikami | K37: Bez funkcji antykoncepcyjnych (inne przeznaczenie, inny reżim).
A38: P1 Eternal App (oprogramowanie) | B38: M61 | C38: Zdrowie dziecka i rodziny | D38: Eternal Women & Family | E38: brak osobnego toru; w torze rodziny MVP 2026 H2 to tylko dostępność | F38: A | G38: Profil dziecka i opiekuna | H38: brak | I38: Kod: APP17 Rodzina i opiekunowie; DAT01 Kanoniczny rekord zdrowia Testy automatyczne i dokumentacja techniczna | J38: Akceptacja zakresu, testy z użytkownikami
A39: P1 Eternal App (oprogramowanie) | B39: M63 | C39: Rehabilitacja / monitoring zdalny | D39: Eternal Senior & Rehab | E39: brak osobnego toru; w torze rodziny MVP 2026 H2 to tylko dostępność | F39: A | G39: Plan terapeuty i rejestr ćwiczeń | H39: brak | I39: Kod: APP25 Senior i rehabilitacja; APP11 Cele i plany Testy automatyczne i dokumentacja techniczna | J39: Akceptacja zakresu, testy z użytkownikami
A40: P2 Eternal Station | B40: M36 | C40: Inteligentny dozownik | D40: Eternal Station Core | E40: wymagania 2026 H2–2027 H2 | F40: A | G40: Przypomnienia; bez fizycznego dozowania | H40: brak | I40: Kod: APP19 Rejestr leków; APP09 Przypomnienia Testy automatyczne i dokumentacja techniczna | J40: Akceptacja zakresu, testy z użytkownikami
...

Sheet P1_APLIKACJA
A1: P1 Eternal App (oprogramowanie)
A2: Moduły produktowe projektu na etapach MVP → MLP → FINAL. Klasa: patrz CZYTAJ.
A3: Moduł ID | B3: Moduł produktowy | C3: Produkt | D3: Etap | E3: Termin wg roadmapy (arkusz 50) | F3: Funkcjonalności i wynik etapu | G3: Zmiana względem poprzedniego etapu | H3: Komponenty: kod pisze AI | I3: Komponenty: AI pisze adapter, człowiek — konto, umowa, licencja lub proces | J3: Komponenty: partner, sprzęt, usługa fizyczna | K3: Komponenty: regulowane lub R&D | L3: Klasa pracy AI | M3: Co zrobi AI | N3: Co zrobi człowiek lub partner | O3: Bramka przejścia / STOP | P3: Stan w Eternal Lite (zakres MVP) | Q3: Konfiguracja (arkusz 45)
A4: M01 | B4: Tożsamość / Eternal ID | C4: Eternal App Core | D4: MVP | E4: 2026 H2 | F4: Logowanie i profil | G4: Wdrożyć minimum dla wyniku tego etapu; nie kupować automatycznie części MLP/FINAL. | H4: DAT01 Kanoniczny rekord zdrowia | I4: SYS01 Dostawca tożsamości | J4: — | K4: — | L4: B | M4: Kod: DAT01 Kanoniczny rekord zdrowia Adaptery i integracje: SYS01 Dostawca tożsamości Testy automatyczne i dokumentacja techniczna | N4: Wybór dostawcy, konto, umowa powierzenia lub licencja: SYS01 Dostawca tożsamości Akceptacja zakresu, testy z użytkownikami | O4: Sprawdzone przypisanie osoby oraz uprawnień | P4: jest: konto, MFA (TOTP, klucze dostępu), logowanie OIDC, sesje mobilne; brak aliasów krajowych | Q4: M01-MVP
A5: M01 | B5: Tożsamość / Eternal ID | C5: Eternal App Core | D5: MLP | E5: 2027 H2 | F5: Zachować bazowe funkcjonalności; rozszerzenie: Role opiekuna i kliniki | G5: Dodać: SYS02, APP17. Wycofać/zastąpić: brak. Zachować kontrakt danych; test regresji i możliwość powrotu. | H5: DAT01 Kanoniczny rekord zdrowia APP17 Rodzina i opiekunowie | I5: SYS01 Dostawca tożsamości SYS02 Bezpieczeństwo urządzenia użytkownika | J5: — | K5: — | L5: B | M5: Kod: DAT01 Kanoniczny rekord zdrowia; APP17 Rodzina i opiekunowie Adaptery i integracje: SYS01 Dostawca tożsamości; SYS02 Bezpieczeństwo urządzenia użytkownika Testy automatyczne i dokumentacja techniczna | N5: Wybór dostawcy, konto, umowa powierzenia lub licencja: SYS01 Dostawca tożsamości; SYS02 Bezpieczeństwo urządzenia użytkownika Akceptacja zakresu, testy z użytkownikami | O5: Sprawdzone przypisanie osoby oraz uprawnień | P5: — | Q5: M01-MLP
A6: M01 | B6: Tożsamość / Eternal ID | C6: Eternal App Core | D6: FINAL | E6: 2029 H1 | F6: Zachować bazowe funkcjonalności; rozszerzenie: Federacja tożsamości i lokalne aliasy | G6: Dodać: SYS05. Wycofać/zastąpić: brak. Zachować kontrakt danych; test regresji i możliwość powrotu. | H6: DAT01 Kanoniczny rekord zdrowia APP17 Rodzina i opiekunowie | I6: SYS01 Dostawca tożsamości SYS02 Bezpieczeństwo urządzenia użytkownika SYS05 Podpis i weryfikacja tożsamości | J6: — | K6: — | L6: B | M6: Kod: DAT01 Kanoniczny rekord zdrowia; APP17 Rodzina i opiekunowie Adaptery i integracje: SYS01 Dostawca tożsamości; SYS02 Bezpieczeństwo urządzenia użytkownika; SYS05 Podpis i weryfikacja tożsamości Testy automatyczne i dokumentacja techniczna | N6: Wybór dostawcy, konto, umowa powierzenia lub licencja: SYS01 Dostawca tożsamości; SYS02 Bezpieczeństwo urządzenia użytkownika; SYS05 Podpis i weryfikacja tożsamości Akceptacja zakresu, testy z użytkownikami | O6: Sprawdzone przypisanie osoby oraz uprawnień | P6: — | Q6: M01-FINAL
A7: M02 | B7: Portfel danych zdrowotnych | C7: Eternal App Core | D7: MVP | E7: 2026 H2 | F7: Import, magazyn dokumentów i eksport | G7: Wdrożyć minimum dla wyniku tego etapu; nie kupować automatycznie części MLP/FINAL. | H7: DAT05 Importer i parser dokumentów DAT03 Pochodzenie danych i wersjonowanie | I7: INF03 Magazyn plików | J7: — | K7: — | L7: B | M7: Kod: DAT05 Importer i parser dokumentów; DAT03 Pochodzenie danych i wersjonowanie Adaptery i integracje: INF03 Magazyn plików Testy automatyczne i dokumentacja techniczna | N7: Wybór dostawcy, konto, umowa powierzenia lub licencja: INF03 Magazyn plików Akceptacja zakresu, testy z użytkownikami | O7: Test eksportu, odwołania dostępu i odtworzenia | P7: jest: dokumenty, wersje FHIR R4, eksport CSV/PDF/FHIR; pliki w bazie zamiast magazynu obiektowego | Q7: M02-MVP
A8: M02 | B8: Portfel danych zdrowotnych | C8: Eternal App Core | D8: MLP | E8: 2027 H2 | F8: Zachować bazowe funkcjonalności; rozszerzenie: Wersjonowanie i kontrola udostępniania | G8: Dodać: DAT01, DAT08. Wycofać/zastąpić: brak. Zachować kontrakt danych; test regresji i możliwość powrotu. | H8: DAT05 Importer i parser dokumentów DAT03 Pochodzenie danych i wersjonowanie DAT01 Kanoniczny rekord zdrowia DAT08 Pakiet udostępnienia | I8: INF03 Magazyn plików | J8: — | K8: — | L8: B | M8: Kod: DAT05 Importer i parser dokumentów; DAT03 Pochodzenie danych i wersjonowanie; DAT01 Kanoniczny rekord zdrowia; DAT08 Pakiet udostępnienia Adaptery i integracje: INF03 Magazyn plików Testy automatyczne i dokumentacja techniczna | N8: Wybór dostawcy, konto, umowa powierzenia lub licencja: INF03 Magazyn plików Akceptacja zakresu, testy z użytkownikami | O8: Test eksportu, odwołania dostępu i odtworzenia | P8: — | Q8: M02-MLP
A9: M02 | B9: Portfel danych zdrowotnych | C9: Eternal App Core | D9: FINAL | E9: 2029 H1 | F9: Zachować bazowe funkcjonalności; rozszerzenie: Przenośny portfel danych z wielu źródeł | G9: Dodać: DAT07, CTL15. Wycofać/zastąpić: brak. Zachować kontrakt danych; test regresji i możliwość powrotu. | H9: DAT05 Importer i parser dokumentów DAT03 Pochodzenie danych i wersjonowanie DAT01 Kanoniczny rekord zdrowia DAT08 Pakiet udostępnienia DAT07 Widok podłużny CTL15 Retencja i eksport | I9: INF03 Magazyn plików | J9: — | K9: — | L9: B | M9: Kod: DAT05 Importer i parser dokumentów; DAT03 Pochodzenie danych i wersjonowanie; DAT01 Kanoniczny rekord zdrowia; DAT08 Pakiet udostępnienia; DAT07 Widok podłużny; CTL15 Retencja i eksport Adaptery i integracje: INF03 Magazyn plików Testy automatyczne i dokumentacja techniczna | N9: Wybór dostawcy, konto, umowa powierzenia lub licencja: INF03 Magazyn plików Akceptacja zakresu, testy z użytkownikami | O9: Test eksportu, odwołania dostępu i odtworzenia | P9: — | Q9: M02-FINAL
A10: M03 | B10: Dokumenty i OCR | C10: Eternal App Core | D10: MVP | E10: 2026 H2 | F10: OCR i korekta użytkownika | G10: Wdrożyć minimum dla wyniku tego etapu; nie kupować automatycznie części MLP/FINAL. | H10: DAT05 Importer i parser dokumentów DAT03 Pochodzenie danych i wersjonowanie | I10: AI01 OCR | J10: — | K10: — | L10: B | M10: Kod: DAT05 Importer i parser dokumentów; DAT03 Pochodzenie danych i wersjonowanie Adaptery i integracje: AI01 OCR Testy automatyczne i dokumentacja techniczna | N10: Wybór dostawcy, konto, umowa powierzenia lub licencja: AI01 OCR Akceptacja zakresu, testy z użytkownikami | O10: Jakość ekstrakcji i koszt dokumentu | P10: częściowo: PDF z tekstem i polski rozbiór wyników; OCR zdjęć gotowy w kodzie, bez konta u dostawcy | Q10: M03-MVP
A11: M03 | B11: Dokumenty i OCR | C11: Eternal App Core | D11: MLP | E11: 2027 H2 | F11: Zachować bazowe funkcjonalności; rozszerzenie: Parser pól, jednostek i deduplikacja | G11: Dodać: DAT04, DAT06. Wycofać/zastąpić: brak. Zachować kontrakt danych; test regresji i możliwość powrotu. | H11: DAT05 Importer i parser dokumentów DAT03 Pochodzenie danych i wersjonowanie DAT04 Deduplikacja i jakość danych | I11: AI01 OCR DAT06 Terminologia | J11: — | K11: — | L11: B | M11: Kod: DAT05 Importer i parser dokumentów; DAT03 Pochodzenie danych i wersjonowanie; DAT04 Deduplikacja i jakość danych Adaptery i integracje: AI01 OCR; DAT06 Terminologia Testy automatyczne i dokumentacja techniczna | N11: Wybór dostawcy, konto, umowa powierzenia lub licencja: AI01 OCR; DAT06 Terminologia Akceptacja zakresu, testy z użytkownikami | O11: Jakość ekstrakcji i koszt dokumentu | P11: — | Q11: M03-MLP
A12: M03 | B12: Dokumenty i OCR | C12: Eternal App Core | D12: FINAL | E12: 2029 H1 | F12: Zachować bazowe funkcjonalności; rozszerzenie: Wiele formatów; własny parser opcjonalnie | G12: Dodać: brak nowych klas. Wycofać/zastąpić: brak. Zachować kontrakt danych; test regresji i możliwość powrotu. | H12: DAT05 Importer i parser dokumentów DAT03 Pochodzenie danych i wersjonowanie DAT04 Deduplikacja i jakość danych | I12: AI01 OCR DAT06 Terminologia | J12: — | K12: — | L12: B | M12: Kod: DAT05 Importer i parser dokumentów; DAT03 Pochodzenie danych i wersjonowanie; DAT04 Deduplikacja i jakość danych Adaptery i integracje: AI01 OCR; DAT06 Terminologia Testy automatyczne i dokumentacja techniczna | N12: Wybór dostawcy, konto, umowa powierzenia lub licencja: AI01 OCR; DAT06 Terminologia Akceptacja zakresu, testy z użytkownikami | O12: Jakość ekstrakcji i koszt dokumentu | P12: — | Q12: M03-FINAL
A13: M04 | B13: Universal Sync | C13: Eternal App Core | D13: MVP | E13: 2027 H1 | F13: Universal Sync: jeden agregator, bez własnego urządzenia noszonego | G13: Wdrożyć minimum dla wyniku tego etapu; nie kupować automatycznie części MLP/FINAL. | H13: DAT01 Kanoniczny rekord zdrowia DAT03 Pochodzenie danych i wersjonowanie DAT04 Deduplikacja i jakość danych | I13: INT03 Adapter Terra | J13: — | K13: — | L13: B | M13: Kod: DAT01 Kanoniczny rekord zdrowia; DAT03 Pochodzenie danych i wersjonowanie; DAT04 Deduplikacja i jakość danych Adaptery i integracje: INT03 Adapter Terra Testy automatyczne i dokumentacja techniczna | N13: Wybór dostawcy, konto, umowa powierzenia lub licencja: INT03 Adapter Terra Akceptacja zakresu, testy z użytkownikami | O13: Urządzenie–metryka–częstotliwość; test migracji; własne urządzenie noszone tylko dla wykazanej luki | P13: częściowo: Withings, Bluetooth w przeglądarce, dane z platform monitoringu (webhook); brak Terra, HealthKit, Health Connect | Q13: M04-MVP
A14: M04 | B14: Universal Sync | C14: Eternal App Core | D14: MLP | E14: 2027 H2 | F14: Zachować bazowe funkcjonalności; rozszerzenie: Drugi przetestowany adapter oraz źródła telefonu/OEM według luk | G14: Dodać: INT04, CTL06, CTL07. Wycofać/zastąpić: brak. Zachować kontrakt danych; test regresji i możliwość powrotu. | H14: DAT01 Kanoniczny rekord zdrowia DAT03 Pochodzenie danych i wersjonowanie DAT04 Deduplikacja i jakość danych CTL06 Router dostawców CTL07 Fabryka adapterów | I14: INT03 Adapter Terra INT04 Adapter bezpośredni OEM | J14: — | K14: — | L14: B | M14: Kod: DAT01 Kanoniczny rekord zdrowia; DAT03 Pochodzenie danych i wersjonowanie; DAT04 Deduplikacja i jakość danych; CTL06 Router dostawców; CTL07 Fabryka adapterów Adaptery i integracje: INT03 Adapter Terra; INT04 Adapter bezpośredni OEM Testy automatyczne i dokumentacja techniczna | N14: Wybór dostawcy, konto, umowa powierzenia lub licencja: INT03 Adapter Terra; INT04 Adapter bezpośredni OEM Akceptacja zakresu, testy z użytkownikami | O14: Urządzenie–metryka–częstotliwość; test migracji; własne urządzenie noszone tylko dla wykazanej luki | P14: — | Q14: M04-MLP
... A129: M69 | B129: Orkiestracja dowodów i AI | C129: Evidence Assistant | D129: FINAL | E129: 2029 H2 | F129: Zachować bazowe funkcjonalności; rozszerzenie: Lekarz wspierany AI; autonomiczny lekarz jako oddzielny cel R&D | G129: Dodać: CTL12. Wycofać/zastąpić: brak. Zachować kontrakt danych; test regresji i możliwość powrotu. | H129: AI04 Retriever RAG AI13 Weryfikator cytowań i odpowiedzi APP12 Treści edukacyjne i audio | I129: AI03 Model językowy INF12 Indeks wyszukiwania CTL12 Jakość i dokumentacja wydania | J129: SVC05 Personel kliniczny | K129: AI07 Model wskazania klinicznego | L129: D | M129: Kod: AI04 Retriever RAG; AI13 Weryfikator cytowań i odpowiedzi; APP12 Treści edukacyjne i audio Adaptery i integracje: AI03 Model językowy; INF12 Indeks wyszukiwania Integracja programowa z: SVC05 Personel kliniczny Kod i dokumentacja techniczna dla: AI07 Model wskazania klinicznego Narzędzia i szablony dokumentów dla: CTL12 Jakość i dokumentacja wydania Testy automatyczne i dokumentacja techniczna | N129: Wybór dostawcy, konto, umowa powierzenia lub licencja: AI03 Model językowy; INF12 Indeks wyszukiwania Umowa z partnerem, zakup lub personel: SVC05 Personel kliniczny Walidacja kliniczna, QMS i dopuszczenie: AI07 Model wskazania klinicznego Prowadzenie procesu: CTL12 Jakość i dokumentacja wydania Akceptacja zakresu, testy z użytkownikami | O129: Ewaluacja; OpenEvidence jako warunkowy zamiennik INT19 po potwierdzeniu praw i zakresu | P129: — | Q129: M69-FINAL

Sheet P2_STATION
A1: P2 Eternal Station
A2: Moduły produktowe projektu na etapach MVP → MLP → FINAL. Klasa: patrz CZYTAJ.
A3: Moduł ID | B3: Moduł produktowy | C3: Produkt | D3: Etap | E3: Termin wg roadmapy (arkusz 50) | F3: Funkcjonalności i wynik etapu | G3: Zmiana względem poprzedniego etapu | H3: Komponenty: kod pisze AI | I3: Komponenty: AI pisze adapter, człowiek — konto, umowa, licencja lub proces | J3: Komponenty: partner, sprzęt, usługa fizyczna | K3: Komponenty: regulowane lub R&D | L3: Klasa pracy AI | M3: Co zrobi AI | N3: Co zrobi człowiek lub partner | O3: Bramka przejścia / STOP | P3: Stan w Eternal Lite (zakres MVP) | Q3: Konfiguracja (arkusz 45)
A4: M32 | B4: Bramka urządzeń | C4: Eternal Station Core | D4: MVP | E4: wymagania 2026 H2–2027 H2 | F4: Telefon lub gotowy gateway | G4: Wdrożyć minimum dla wyniku tego etapu; nie kupować automatycznie części MLP/FINAL. | H4: INT05 Adapter BLE i lokalny gateway DAT01 Kanoniczny rekord zdrowia | I4: — | J4: HW04 Gateway domowy | K4: — | L4: C | M4: Kod: INT05 Adapter BLE i lokalny gateway; DAT01 Kanoniczny rekord zdrowia Integracja programowa z: HW04 Gateway domowy Testy automatyczne i dokumentacja techniczna | N4: Umowa z partnerem, zakup lub personel: HW04 Gateway domowy Akceptacja zakresu, testy z użytkownikami | O4: Zgodność sprzętu, brak sieci i koszt serwisu | P4: brak | Q4: M32-MVP
A5: M32 | B5: Bramka urządzeń | C5: Eternal Station Core | D5: MLP | E5: 2028 H1 | F5: Zachować bazowe funkcjonalności; rozszerzenie: Parowanie i buforowanie offline | G5: Dodać: SYS06, CTL16. Wycofać/zastąpić: brak. Zachować kontrakt danych; test regresji i możliwość powrotu. | H5: INT05 Adapter BLE i lokalny gateway DAT01 Kanoniczny rekord zdrowia SYS06 Offline i synchronizacja klienta CTL16 Rejestr urządzeń | I5: — | J5: HW04 Gateway domowy | K5: — | L5: C | M5: Kod: INT05 Adapter BLE i lokalny gateway; DAT01 Kanoniczny rekord zdrowia; SYS06 Offline i synchronizacja klienta; CTL16 Rejestr urządzeń Integracja programowa z: HW04 Gateway domowy Testy automatyczne i dokumentacja techniczna | N5: Umowa z partnerem, zakup lub personel: HW04 Gateway domowy Akceptacja zakresu, testy z użytkownikami | O5: Zgodność sprzętu, brak sieci i koszt serwisu | P5: — | Q5: M32-MLP
A6: M32 | B6: Bramka urządzeń | C6: Eternal Station Core | D6: FINAL | E6: 2029 H2 | F6: Zachować bazowe funkcjonalności; rozszerzenie: Zarządzana flota; ODM opcjonalnie | G6: Dodać: HW16. Wycofać/zastąpić: brak. Zachować kontrakt danych; test regresji i możliwość powrotu. | H6: INT05 Adapter BLE i lokalny gateway DAT01 Kanoniczny rekord zdrowia SYS06 Offline i synchronizacja klienta CTL16 Rejestr urządzeń | I6: — | J6: HW04 Gateway domowy HW16 Firmware i aktualizacje | K6: — | L6: C | M6: Kod: INT05 Adapter BLE i lokalny gateway; DAT01 Kanoniczny rekord zdrowia; SYS06 Offline i synchronizacja klienta; CTL16 Rejestr urządzeń Integracja programowa z: HW04 Gateway domowy; HW16 Firmware i aktualizacje Testy automatyczne i dokumentacja techniczna | N6: Umowa z partnerem, zakup lub personel: HW04 Gateway domowy; HW16 Firmware i aktualizacje Akceptacja zakresu, testy z użytkownikami | O6: Zgodność sprzętu, brak sieci i koszt serwisu | P6: — | Q6: M32-FINAL
A7: M33 | B7: Diagnostyka podstawowa | C7: Eternal Station Core | D7: MVP | E7: wymagania 2026 H2–2027 H2 | F7: Zestaw gotowych urządzeń pomiarowych | G7: Wdrożyć minimum dla wyniku tego etapu; nie kupować automatycznie części MLP/FINAL. | H7: APP02 Raport i zestawienie | I7: — | J7: HW01 Zatwierdzone urządzenie pomiarowe | K7: — | L7: C | M7: Kod: APP02 Raport i zestawienie Integracja programowa z: HW01 Zatwierdzone urządzenie pomiarowe Testy automatyczne i dokumentacja techniczna | N7: Umowa z partnerem, zakup lub personel: HW01 Zatwierdzone urządzenie pomiarowe Akceptacja zakresu, testy z użytkownikami | O7: Każdy pomiar wymaga odpowiedniego urządzenia i jego wskazania | P7: brak | Q7: M33-MVP
A8: M33 | B8: Diagnostyka podstawowa | C8: Eternal Station Core | D8: MLP | E8: 2028 H1 | F8: Zachować bazowe funkcjonalności; rozszerzenie: Wspólny przebieg pomiaru | G8: Dodać: INT05, CTL16. Wycofać/zastąpić: brak. Zachować kontrakt danych; test regresji i możliwość powrotu. | H8: APP02 Raport i zestawienie INT05 Adapter BLE i lokalny gateway CTL16 Rejestr urządzeń | I8: — | J8: HW01 Zatwierdzone urządzenie pomiarowe | K8: — | L8: C | M8: Kod: APP02 Raport i zestawienie; INT05 Adapter BLE i lokalny gateway; CTL16 Rejestr urządzeń Integracja programowa z: HW01 Zatwierdzone urządzenie pomiarowe Testy automatyczne i dokumentacja techniczna | N8: Umowa z partnerem, zakup lub personel: HW01 Zatwierdzone urządzenie pomiarowe Akceptacja zakresu, testy z użytkownikami | O8: Każdy pomiar wymaga odpowiedniego urządzenia i jego wskazania | P8: — | Q8: M33-MLP
A9: M33 | B9: Diagnostyka podstawowa | C9: Eternal Station Core | D9: FINAL | E9: 2029 H2 | F9: Zachować bazowe funkcjonalności; rozszerzenie: Rozbudowa o potrzebną diagnostykę | G9: Dodać: HW06, APP30. Wycofać/zastąpić: brak. Zachować kontrakt danych; test regresji i możliwość powrotu. | H9: APP02 Raport i zestawienie INT05 Adapter BLE i lokalny gateway CTL16 Rejestr urządzeń APP30 Operacje placówki | I9: — | J9: HW01 Zatwierdzone urządzenie pomiarowe HW06 Analizator POCT | K9: — | L9: C | M9: Kod: APP02 Raport i zestawienie; INT05 Adapter BLE i lokalny gateway; CTL16 Rejestr urządzeń; APP30 Operacje placówki Integracja programowa z: HW01 Zatwierdzone urządzenie pomiarowe; HW06 Analizator POCT Testy automatyczne i dokumentacja techniczna | N9: Umowa z partnerem, zakup lub personel: HW01 Zatwierdzone urządzenie pomiarowe; HW06 Analizator POCT Akceptacja zakresu, testy z użytkownikami | O9: Każdy pomiar wymaga odpowiedniego urządzenia i jego wskazania | P9: — | Q9: M33-FINAL
A10: M34 | B10: Przebieg zdalnego monitoringu | C10: Eternal RPM Home | D10: MVP | E10: wymagania 2026 H2–2027 H2 | F10: RPM na platformie partnera z zespołem opieki | G10: Wdrożyć minimum dla wyniku tego etapu; nie kupować automatycznie części MLP/FINAL. | H10: — | I10: — | J10: INT10 Vitalera Platform HW01 Zatwierdzone urządzenie pomiarowe SVC05 Personel kliniczny | K10: — | L10: C | M10: Integracja programowa z: INT10 Vitalera Platform; HW01 Zatwierdzone urządzenie pomiarowe; SVC05 Personel kliniczny Testy automatyczne i dokumentacja techniczna | N10: Umowa z partnerem, zakup lub personel: INT10 Vitalera Platform; HW01 Zatwierdzone urządzenie pomiarowe; SVC05 Personel kliniczny Akceptacja zakresu, testy z użytkownikami | O10: SLA pomiaru i reakcji; brak aplikacji tylko dla potwierdzonej konfiguracji sprzętowej | P10: brak | Q10: M34-MVP
A11: M34 | B11: Przebieg zdalnego monitoringu | C11: Eternal RPM Home | D11: MLP | E11: 2028 H1 | F11: Zachować bazowe funkcjonalności; rozszerzenie: Własny przebieg pracy i API/SDK partnera | G11: Dodać: INT07, APP03, CTL18. Wycofać/zastąpić: INT10. Zachować kontrakt danych; test regresji i możliwość powrotu. | H11: APP03 Skrzynka i kolejka pracy CTL18 Reguły i orkiestracja | I11: INT07 Adapter Vitalera API | J11: HW01 Zatwierdzone urządzenie pomiarowe SVC05 Personel kliniczny | K11: — | L11: C | M11: Kod: APP03 Skrzynka i kolejka pracy; CTL18 Reguły i orkiestracja Adaptery i integracje: INT07 Adapter Vitalera API Integracja programowa z: HW01 Zatwierdzone urządzenie pomiarowe; SVC05 Personel kliniczny Testy automatyczne i dokumentacja techniczna | N11: Wybór dostawcy, konto, umowa powierzenia lub licencja: INT07 Adapter Vitalera API Umowa z partnerem, zakup lub personel: HW01 Zatwierdzone urządzenie pomiarowe; SVC05 Personel kliniczny Akceptacja zakresu, testy z użytkownikami | O11: SLA pomiaru i reakcji; brak aplikacji tylko dla potwierdzonej konfiguracji sprzętowej | P11: — | Q11: M34-MLP
A12: M34 | B12: Przebieg zdalnego monitoringu | C12: Eternal RPM Home | D12: FINAL | E12: 2029 H2 | F12: Zachować bazowe funkcjonalności; rozszerzenie: RPM wielu dostawców | G12: Dodać: INT04, CTL06. Wycofać/zastąpić: brak. Zachować kontrakt danych; test regresji i możliwość powrotu. | H12: APP03 Skrzynka i kolejka pracy CTL18 Reguły i orkiestracja CTL06 Router dostawców | I12: INT07 Adapter Vitalera API INT04 Adapter bezpośredni OEM | J12: HW01 Zatwierdzone urządzenie pomiarowe SVC05 Personel kliniczny | K12: — | L12: C | M12: Kod: APP03 Skrzynka i kolejka pracy; CTL18 Reguły i orkiestracja; CTL06 Router dostawców Adaptery i integracje: INT07 Adapter Vitalera API; INT04 Adapter bezpośredni OEM Integracja programowa z: HW01 Zatwierdzone urządzenie pomiarowe; SVC05 Personel kliniczny Testy automatyczne i dokumentacja techniczna | N12: Wybór dostawcy, konto, umowa powierzenia lub licencja: INT07 Adapter Vitalera API; INT04 Adapter bezpośredni OEM Umowa z partnerem, zakup lub personel: HW01 Zatwierdzone urządzenie pomiarowe; SVC05 Personel kliniczny Akceptacja zakresu, testy z użytkownikami | O12: SLA pomiaru i reakcji; brak aplikacji tylko dla potwierdzonej konfiguracji sprzętowej | P12: — | Q12: M34-FINAL
A13: M35 | B13: Zestaw Care Pod | C13: Eternal Care Pod | D13: MVP | E13: wymagania 2026 H2–2027 H2 | F13: Care Pod jako zestaw w placówce partnera | G13: Wdrożyć minimum dla wyniku tego etapu; nie kupować automatycznie części MLP/FINAL. | H13: — | I13: APP07 Wideokonsultacja | J13: HW01 Zatwierdzone urządzenie pomiarowe SVC05 Personel kliniczny SVC08 Klinika | K13: — | L13: C | M13: Adaptery i integracje: APP07 Wideokonsultacja Integracja programowa z: HW01 Zatwierdzone urządzenie pomiarowe; SVC05 Personel kliniczny; SVC08 Klinika Testy automatyczne i dokumentacja techniczna | N13: Wybór dostawcy, konto, umowa powierzenia lub licencja: APP07 Wideokonsultacja Umowa z partnerem, zakup lub personel: HW01 Zatwierdzone urządzenie pomiarowe; SVC05 Personel kliniczny; SVC08 Klinika Akceptacja zakresu, testy z użytkownikami | O13: Obłożenie, personel, marża; pod nie zastępuje organizacji kliniki/szpitala | P13: brak | Q13: M35-MVP
A14: M35 | B14: Zestaw Care Pod | C14: Eternal Care Pod | D14: MLP | E14: 2028 H1 | F14: Zachować bazowe funkcjonalności; rozszerzenie: Punkt obsługi z gateway i badaniami | G14: Dodać: HW04, APP30, SVC01. Wycofać/zastąpić: brak. Zachować kontrakt danych; test regresji i możliwość powrotu. | H14: APP30 Operacje placówki | I14: APP07 Wideokonsultacja | J14: HW01 Zatwierdzone urządzenie pomiarowe SVC05 Personel kliniczny SVC08 Klinika HW04 Gateway domowy SVC01 Laboratorium wykonujące badanie | K14: — | L14: C | M14: Kod: APP30 Operacje placówki Adaptery i integracje: APP07 Wideokonsultacja Integracja programowa z: HW01 Zatwierdzone urządzenie pomiarowe; SVC05 Personel kliniczny; SVC08 Klinika; HW04 Gateway domowy; SVC01 Laboratorium wykonujące badanie Testy automatyczne i dokumentacja techniczna | N14: Wybór dostawcy, konto, umowa powierzenia lub licencja: APP07 Wideokonsultacja Umowa z partnerem, zakup lub personel: HW01 Zatwierdzone urządzenie pomiarowe; SVC05 Personel kliniczny; SVC08 Klinika; HW04 Gateway domowy; SVC01 Laboratorium wykonujące badanie Akceptacja zakresu, testy z użytkownikami | O14: Obłożenie, personel, marża; pod nie zastępuje organizacji kliniki/szpitala | P14: — | Q14: M35-MLP
... A24: M38 | B24: Bezpieczeństwo i rehabilitacja | C24: Eternal Rehab & Senior Station | D24: FINAL | E24: 2029 H2 | F24: Zachować bazowe funkcjonalności; rozszerzenie: Program bezpieczeństwa i rehabilitacji | G24: Dodać: CTL18, SVC05. Wycofać/zastąpić: brak. Zachować kontrakt danych; test regresji i możliwość powrotu. | H24: APP25 Senior i rehabilitacja APP09 Przypomnienia APP17 Rodzina i opiekunowie CTL18 Reguły i orkiestracja | I24: AI06 Ocena pozy ruchowej | J24: HW01 Zatwierdzone urządzenie pomiarowe SVC05 Personel kliniczny | K24: — | L24: C | M24: Kod: APP25 Senior i rehabilitacja; APP09 Przypomnienia; APP17 Rodzina i opiekunowie; CTL18 Reguły i orkiestracja Adaptery i integracje: AI06 Ocena pozy ruchowej Integracja programowa z: HW01 Zatwierdzone urządzenie pomiarowe; SVC05 Personel kliniczny Testy automatyczne i dokumentacja techniczna | N24: Wybór dostawcy, konto, umowa powierzenia lub licencja: AI06 Ocena pozy ruchowej Umowa z partnerem, zakup lub personel: HW01 Zatwierdzone urządzenie pomiarowe; SVC05 Personel kliniczny Akceptacja zakresu, testy z użytkownikami | O24: Fałszywe alarmy, odbiór przez opiekuna i efekt programu | P24: — | Q24: M38-FINAL

Sheet P3_CAPSULE
A1: P3 Eternal Capsule
A2: Moduły produktowe projektu na etapach MVP → MLP → FINAL. Klasa: patrz CZYTAJ.
A3: Moduł ID | B3: Moduł produktowy | C3: Produkt | D3: Etap | E3: Termin wg roadmapy (arkusz 50) | F3: Funkcjonalności i wynik etapu | G3: Zmiana względem poprzedniego etapu | H3: Komponenty: kod pisze AI | I3: Komponenty: AI pisze adapter, człowiek — konto, umowa, licencja lub proces | J3: Komponenty: partner, sprzęt, usługa fizyczna | K3: Komponenty: regulowane lub R&D | L3: Klasa pracy AI | M3: Co zrobi AI | N3: Co zrobi człowiek lub partner | O3: Bramka przejścia / STOP | P3: Stan w Eternal Lite (zakres MVP) | Q3: Konfiguracja (arkusz 45)
A4: M39 | B4: Protokół / rejestr urządzeń | C4: Capsule Gateway | D4: MVP | E4: przegląd, bez terminu | F4: Rejestr urządzeń i raportów | G4: Wdrożyć minimum dla wyniku tego etapu; nie kupować automatycznie części MLP/FINAL. | H4: CTL16 Rejestr urządzeń DAT05 Importer i parser dokumentów | I4: — | J4: — | K4: — | L4: A | M4: Kod: CTL16 Rejestr urządzeń; DAT05 Importer i parser dokumentów Testy automatyczne i dokumentacja techniczna | N4: Akceptacja zakresu, testy z użytkownikami | O4: Umowa OEM i bezpieczeństwo; bez własnego implantu | P4: brak | Q4: M39-MVP
A5: M39 | B5: Protokół / rejestr urządzeń | C5: Capsule Gateway | D5: MLP | E5: przegląd, bez terminu | F5: Zachować bazowe funkcjonalności; rozszerzenie: Adapter partnera i metadane firmware | G5: Dodać: INT04, HW16. Wycofać/zastąpić: brak. Zachować kontrakt danych; test regresji i możliwość powrotu. | H5: CTL16 Rejestr urządzeń DAT05 Importer i parser dokumentów | I5: INT04 Adapter bezpośredni OEM | J5: HW16 Firmware i aktualizacje | K5: — | L5: C | M5: Kod: CTL16 Rejestr urządzeń; DAT05 Importer i parser dokumentów Adaptery i integracje: INT04 Adapter bezpośredni OEM Integracja programowa z: HW16 Firmware i aktualizacje Testy automatyczne i dokumentacja techniczna | N5: Wybór dostawcy, konto, umowa powierzenia lub licencja: INT04 Adapter bezpośredni OEM Umowa z partnerem, zakup lub personel: HW16 Firmware i aktualizacje Akceptacja zakresu, testy z użytkownikami | O5: Umowa OEM i bezpieczeństwo; bez własnego implantu | P5: — | Q5: M39-MLP
A6: M39 | B6: Protokół / rejestr urządzeń | C6: Capsule Gateway | D6: FINAL | E6: przegląd, bez terminu | F6: Zachować bazowe funkcjonalności; rozszerzenie: Protokół wielu dostawców | G6: Dodać: CTL07. Wycofać/zastąpić: brak. Zachować kontrakt danych; test regresji i możliwość powrotu. | H6: CTL16 Rejestr urządzeń DAT05 Importer i parser dokumentów CTL07 Fabryka adapterów | I6: INT04 Adapter bezpośredni OEM | J6: HW16 Firmware i aktualizacje | K6: — | L6: C | M6: Kod: CTL16 Rejestr urządzeń; DAT05 Importer i parser dokumentów; CTL07 Fabryka adapterów Adaptery i integracje: INT04 Adapter bezpośredni OEM Integracja programowa z: HW16 Firmware i aktualizacje Testy automatyczne i dokumentacja techniczna | N6: Wybór dostawcy, konto, umowa powierzenia lub licencja: INT04 Adapter bezpośredni OEM Umowa z partnerem, zakup lub personel: HW16 Firmware i aktualizacje Akceptacja zakresu, testy z użytkownikami | O6: Umowa OEM i bezpieczeństwo; bez własnego implantu | P6: — | Q6: M39-FINAL
