Workbook

Sheet CZYTAJ
B1: ETERNAL 11.1 — WYBÓR ROZWIĄZAŃ RYNKOWYCH DLA FUNKCJI MVP
B2: Skoroszyt towarzyszący plikowi ETERNAL_11_1_FUNKCJE.xlsx. Stan rynku sprawdzony 4 i 14 października 2026 r.
B5: 1. Do czego służy
B6: Dla każdej funkcji MVP z pliku 11.1 wskazuje gotowe rozwiązanie z rynku (open source, bezpłatne, płatne z UE/PL, płatne globalne), wybór na każdy etap (Demo, MVP, MLP, FINAL) i to, co budujemy sami obok, żeby korzystać z gotowych rozwiązań, ale je kontrolować.
B7: Wybory sprawdzono w sieci (ceny, licencje, dostępność w UE, zmiany 2025–2026) i porównano z ★ z pliku 11.1, gdzie „Stan sprawdzenia” brzmiał „niesprawdzone”.
B9: 2. Arkusze
B10: W1_WYBOR | D10: Zdolność → opcje open source / bezpłatne / płatne → ★ na każdy etap, uzasadnienie, nasza warstwa, wyzwalacz zmiany, łatwość wyjścia, zgodność, stan w aplikacji, źródła.
B11: W2_KOMPONENTY | D11: Wspólne komponenty techniczne (aplikacja mobilna, baza, kolejki, brama modeli, obserwowalność, CI, klucze, kopie) — spójne z działającą aplikacją Eternal.
B12: W3_FUNKCJE_MVP | D12: Każda funkcja MVP z pliku 11.1 (kod jak w Z1) → ID wyboru; kolumny z W1 liczą się formułami. Kolumna R: uwagi tylko dla tej funkcji (np. granica MDR).
B13: W4_KOSZTY | D13: Koszt zewnętrzny wybranych usług na etapach przy założonej skali; założenia i ceny do edycji (niebieskie), wyniki formułami.
B14: W5_ZMIANY_RYNKU | D14: Zdarzenia z rynku i prawa, które zmieniły wybór względem pliku (np. wycofanie OpenEvidence z UE, nowe zasady API Strava, AI Omnibus).
B15: W6_ZRODLA | D15: Źródła z datą sprawdzenia; lista rzeczy niesprawdzonych.
B17: 3. Etapy
B18: DEMO (IV kw. 2026) | D18: Prototyp na danych zespołu i danych syntetycznych; zero opłat stałych; to, co już działa w aplikacji Eternal (app/).
B19: MVP — pierwsze wydanie | D19: Pierwsze wydanie produktu wg pliku (Z7, „Wydanie produktu”): dla produktów 2027 — rok 2027; dla produktów z pierwszym wydaniem w 2028 (np. Wellness) — 2028.
B20: MLP (2028+) | D20: Skala i pakiety płatne: usługi zarządzane tam, gdzie utrzymanie własne przestaje się opłacać; partnerzy z CE.
B21: FINAL (2029–2030) | D21: Wiele krajów, suwerenność danych, modele własne/otwarte tam, gdzie wolumen to uzasadnia.
B23: 4. Model: korzystamy z gotowych i kontrolujemy
B24: Rdzeń danych — open source u nas, w UE | D24: Rekord FHIR (Medplum), tożsamość (Keycloak), zgody, dziennik zdarzeń, uprawnienia — tu jest wartość i ryzyko, więc nie oddajemy ich dostawcy.
B25: Silniki-towary — kupujemy za naszym adapterem | D25: OCR, modele językowe, transkrypcja, SMS, e-mail, push: zawsze przez naszą warstwę z drugim dostawcą w odwodzie (łatwość wyjścia 5).
B26: Funkcje będące wyrobem medycznym — partner z CE | D26: Interpretacja wyników, triaż, alarmy, wykrywanie upadków: robi partner z certyfikatem, my pokazujemy wynik z oznaczeniem źródła.
B27: Dane publiczne — bezpłatnie, kopia u nas | D27: RPL, NFZ, GIOŚ, IMGW, LOINC, ICD, Open Food Facts.
B28: Budujemy sami tylko przewagę | D28: Polski parser wyników, zgody i udostępnienia, raport dla lekarza, panel placówki, ścieżka kryzysowa — tego nie ma na rynku albo to nasz wyróżnik.
B30: 5. Kolumna „Zmiana względem pliku 11.1”
B31: BEZ ZMIAN | D31: ★ z pliku potwierdzony.
B32: DOPRECYZOWANIE | D32: Ten sam dostawca, ale inny etap, sposób wdrożenia albo rola (np. Medplum na własnej infrastrukturze zamiast hostowanego).
B33: ZMIANA | D33: Inny wybór, bo na 10.2026 jest lepsze rozwiązanie dla wymagań (koszt wyjścia, region UE, język polski, licencja, zasady stałe).
B34: ZMIANA — WYMUSZONA RYNKIEM | D34: ★ z pliku przestał być dostępny lub dopuszczalny (wycofanie z UE, zmiana regulaminu API).
B36: 6. Najważniejsze decyzje
B37: • Tożsamość: Keycloak u nas zamiast Amazon Cognito — brak opłat za użytkownika i brak blokady (Cognito nie eksportuje skrótów haseł).
B38: • Asystent wiedzy: OpenEvidence wycofał się z UE (28.04.2026) → DR.INFO dla lekarzy; dla pacjenta własny asystent na treściach redakcyjnych.
B39: • Transkrypcja i Scribe: Corti nie obsługuje polskiego, OpenAI bez potwierdzonej rezydencji UE → ElevenLabs Scribe (UE) + Claude przez Bedrock UE + zatwierdzenie lekarza.
B40: • Dane sportowe: Strava zakazuje użycia danych w AI, Garmin wstrzymał nabór → dane z systemu telefonu + Open Wearables (MIT), Thryve od MLP.
B41: • OCR: najpierw warstwa tekstowa PDF (0 zł), skany przez Mistral OCR 4 (UE); Google Document AI jako zamiennik.
B42: • Rezerwacje: nasz silnik terminów jest rdzeniem; ZnanyLekarz jako kanał przez Docplanner Integrations API.
B43: • E-recepty: wystawia system gabinetowy placówki (MyDr, Medfile, KS-SOMED, mMedica, gabinet.gov.pl); konektor P1 dopiero, gdy Eternal Doctor stanie się systemem placówki.
B44: • Bezpieczeństwo łańcucha dostaw: po kompromitacji Trivy (03.2026) — Grype/OSV-Scanner + Syft, akcje CI przypięte do skrótu.
B45: • Rekord zdrowia: Medplum na własnej infrastrukturze w UE (hostowany: od 2 000 USD/mies., region UE niepotwierdzony).
B46: • Suplementy partnera i odznaki NFT — wyłączone z MVP: konflikt z zasadami stałymi (sterowanie zakupami, tokeny pieniężne).
B48: 7. Liczby (liczone formułami z W1 i W3)
...

Sheet W1_WYBOR
A1: W1 — WYBÓR ROZWIĄZANIA DLA KAŻDEJ ZDOLNOŚCI I ETAPU (stan rynku: 10.2026)
A2: Jeden wiersz = jedna zdolność rynkowa z pliku 11.1 (Z1, kolumna „Co kupujemy”). Kolumny ★ to wybór na etap; „Zmiana” porównuje z ★ w pliku 11.1.
A3: Kolory „Zmiana”: zielony = bez zmian, żółty = doprecyzowanie, pomarańczowy = zmiana, ciemniejszy = zmiana wymuszona rynkiem. Łatwość wyjścia: 5 = wymiana bez przepisywania, 1 = trwałe uzależnienie. Liczba funkcji MVP liczy się z arkusza W3.
A5: ID wyboru | B5: Zdolność / moduł | C5: Zdolność w pliku 11.1 (Z1, kol. „Co kupujemy”) | D5: Funkcje zbiorcze (nr Z3) | E5: Funkcji MVP (z W3) | F5: Model budowy: korzystamy i kontrolujemy | G5: Open source — najlepsze opcje | H5: Bezpłatne (publiczne dane, plany bezpłatne, funkcje systemu) | I5: Płatne — dostawcy z UE / Polski | J5: Płatne — dostawcy globalni | K5: ★ DEMO (IV kw. 2026) | L5: ★ MVP (2027) | M5: ★ MLP (2028) | N5: ★ FINAL (2029–2030) | O5: ★ w pliku 11.1 | P5: Zmiana względem pliku 11.1 | Q5: Dlaczego ten wybór (stan na 10.2026) | R5: Nasza warstwa — co budujemy i kontrolujemy obok | S5: Wyzwalacz zmiany / przejścia etapu | T5: Łatwość wyjścia (1–5) | U5: Zgodność i ryzyko (RODO, MDR, AI Act, licencja) | V5: Stan w działającej aplikacji Eternal (app/) | W5: Stan sprawdzenia i źródła (arkusz W6)
A6: W-01 | B6: Tożsamość, logowanie i sesje | C6: Serwer albo usługa tożsamości (konto, logowanie, sesje, drugi składnik, klucze dostępu) | D6: 1 | E6: =COUNTIF(W3_FUNKCJE_MVP!$L$6:$L$400,$A6) -> 6 | F6: BIERZEMY OPEN SOURCE + nasza warstwa | G6: Keycloak 26 (Apache 2.0, CNCF); Ory Kratos/Hydra (Apache 2.0); Zitadel (od v3 AGPL-3.0) | H6: Amazon Cognito Lite/Essentials — 0 zł do 10 000 aktywnych użytkowników/mies.; Zitadel Cloud Free (100 aktywnych dziennie) | I6: Zitadel Cloud Pro (region UE/CH; 100 USD/mies. do 25 tys. aktywnych dziennie) | J6: Amazon Cognito Essentials (0,015 USD za aktywnego >10 tys.); Microsoft Entra External ID; Auth0 | K6: Obecny moduł logowania aplikacji Eternal (e-mail + hasło, TOTP, sesje) — 0 zł | L6: Keycloak w naszej chmurze UE jako dostawca OIDC: klucze dostępu (WebAuthn/FIDO2), logowanie Apple/Google, TOTP, link e-mail, sesje i urządzenia; PIN i biometria lokalnie w aplikacji mobilnej | M6: Keycloak w klastrze (wysoka dostępność); organizacje = placówki; SMS jako drugi składnik tylko awaryjnie | N6: Keycloak + EUDI Wallet i login.gov.pl jako zewnętrzni dostawcy tożsamości | O6: Amazon Cognito (6) | P6: ZMIANA | Q6: Decyduje kontrola i koszt wyjścia, nie cena: na MVP oba warianty kosztują podobnie (Cognito bezpłatny do 10 tys. aktywnych), przy 150 tys. aktywnych Cognito to ok. 7,8 tys. zł/mies. (W4, sekcja E). Cognito nie pozwala wyeksportować skrótów haseł (wyjście = reset haseł albo migracja przy logowaniu) — najwyższy koszt zmiany w całym stosie. Keycloak: dane logowania w naszej chmurze UE, standard OIDC. Cognito zostaje zapasem, gdy zespół nie utrzyma serwera. | R6: Powiązanie konta z rekordem FHIR (Patient/Practitioner), role, zgody, polityka sesji i urządzeń (max 5), dziennik logowań widoczny dla użytkownika, kody odzyskiwania, PIN w aplikacji | S6: >50 tys. aktywnych albo wymóg SLA 99,9% → klaster lub usługa zarządzana Keycloak; dostępny EUDI Wallet → dodać dostawcę | T6: 5 | U6: Dane logowania w UE; OWASP ASVS L2; MFA obowiązkowe dla personelu; Zitadel AGPL — sprawdzić skutki licencji przy modyfikacjach | V6: Zaimplementowane własne logowanie (scrypt, TOTP z ochroną przed powtórzeniem, sesje, CSRF, HIBP); do podłączenia jako klient OIDC | W6: sprawdzone 04.10.2026 [Z01, Z17, Z72]
A7: W-02 | B7: Bramka SMS | C7: Bramka SMS | D7: 1, 8 | E7: =COUNTIF(W3_FUNKCJE_MVP!$L$6:$L$400,$A7) -> 1 | F7: KUPUJEMY USŁUGĘ + nasza warstwa | G7: — (bramka to usługa operatora) | H7: Brak — na Demo e-mail zamiast SMS | I7: SMSAPI.pl (PL); SerwerSMS.pl (PL); OVHcloud SMS (FR; 0,109–0,135 zł netto/SMS) | J7: Twilio; Vonage; Bird | K7: E-mail zamiast SMS; konto testowe SMSAPI | L7: SMSAPI.pl (już podłączone w aplikacji) — wyłącznie kody i przypomnienia bez danych o zdrowiu | M7: SMSAPI.pl + zapasowy OVHcloud SMS (przełączanie w naszej warstwie kanałów) | N7: Dwóch dostawców na każdy kraj (warstwa krajowa) | O7: SMSAPI.pl (1) | P7: BEZ ZMIAN | Q7: Polski dostawca, nadawca alfanumeryczny, umowa powierzenia po polsku; integracja gotowa. Twilio (F1.8) droższy i bez przewagi w PL. | R7: Abstrakcja kanału, szablony bez danych o zdrowiu, zgody na kanał, limity, kolejka z ponowieniami, przełączanie dostawcy | S7: Awaria lub zmiana cen → zapasowy dostawca; nowy kraj → dostawca lokalny | T7: 5 | U7: Numer telefonu = dane osobowe (umowa powierzenia); treść bez informacji o zdrowiu | V7: Zaimplementowane: SMSAPI.pl i bramka webhook, normalizacja numerów | W7: sprawdzone 04.10.2026 [Z28]; cena SMSAPI niesprawdzona (strona zablokowana przez sieć)
A8: W-03 | B8: Potwierdzenie tożsamości (KYC) | C8: — (komponent wspólny; brak funkcji MVP z tą zdolnością w Z1) | D8: 1 | E8: =COUNTIF(W3_FUNKCJE_MVP!$L$6:$L$400,$A8) -> 0 | F8: POŚREDNICTWO PARTNERA + metody bezpłatne | G8: — | H8: Kod aktywacyjny wydany w placówce po okazaniu dokumentu; mObywatel — weryfikacja mDowodu (kod QR / 6 cyfr przez API mObywatel dla podmiotów) | I8: Authologic (PL; jedno API: bank, szybki przelew i BLIK z Przelewy24, mObywatel, e-dowód; cena na zapytanie); IDnow (DE) | J8: Veriff; Onfido (Entrust) | K8: Kod aktywacyjny z placówki (gotowe w aplikacji) | L8: Kod z placówki + mObywatel tam, gdzie pacjent go ma — 0 zł | M8: Authologic — zdalne potwierdzenie bez wizyty (pakiety B2C) | N8: EUDI Wallet + Authologic | O8: Authologic (Z3, funkcja zbiorcza 1, komponent 3) | P8: DOPRECYZOWANIE | Q8: Na MVP pacjenci przychodzą przez placówki — tożsamość potwierdza placówka bez kosztu. Płatny KYC dopiero, gdy rośnie samodzielna rejestracja B2C. | R8: Poziom pewności tożsamości na koncie, powiązanie z PESEL, dziennik potwierdzeń | S8: Udział rejestracji B2C bez placówki >30% → Authologic | T8: 4 | U8: PESEL i dokument tożsamości — minimalizacja; nie przechowujemy skanów dokumentów | V8: Zaimplementowane: weryfikacja w placówce i kody aktywacyjne | W8: sprawdzone 14.10.2026 [Z18, Z67]; warunki API mObywatel do potwierdzenia
A9: W-04 | B9: Uprawnienia i udostępnianie (kto, co, komu, na jak długo) | C9: Silnik uprawnień (kto, co, komu i na jak długo może pokazać) | D9: 2, 31 | E9: =COUNTIF(W3_FUNKCJE_MVP!$L$6:$L$400,$A9) -> 2 | F9: BIERZEMY OPEN SOURCE + nasza warstwa | G9: OpenFGA (Apache 2.0, CNCF incubating od 10.2025); Open Policy Agent (CNCF graduated); Cedar (Apache 2.0); SpiceDB (Apache 2.0) | H9: Zasady dostępu serwera FHIR (Medplum AccessPolicy) — w cenie serwera | I9: — | J9: Auth0 FGA (Okta); AuthZed (SpiceDB); Amazon Verified Permissions (Cedar); Permit.io | K9: Reguły w kodzie + zasób Consent (gotowe) | L9: Zasady dostępu Medplum + nasz moduł udostępnień czasowych (FHIR Consent z okresem) — bez osobnego silnika | M9: OpenFGA dla relacji pacjent–opiekun–lekarz–placówka i dostępu czasowego | N9: OpenFGA + polityki OPA/Cedar dla reguł krajowych | O9: Open Policy Agent (OPA) (2) | P9: ZMIANA | Q9: Model „kto komu i na jak długo” to relacje (ReBAC) — lepiej pasuje OpenFGA niż ogólny silnik polityk OPA. Na MVP wystarcza Medplum + Consent. Główni opiekunowie OPA przeszli do Apple (2025); projekt pozostaje w CNCF. | R9: Model zgód, okres udostępnienia, wycofanie, „kto oglądał”, testy reguł dostępu | S9: >3 typy relacji (rodzina, opiekun, zespół kliniki) albo reguły krajowe → OpenFGA | T9: 4 | U9: Art. 9 RODO — dostęp tylko na podstawie zgody/umowy; każdy odczyt w dzienniku | V9: Zaimplementowane: role, zgody FHIR Consent, udostępnianie wyników przez placówkę, potwierdzenia odczytu | W9: sprawdzone 04.10.2026 [Z39, Z40]
A10: W-05 | B10: Niezmienialny dziennik zdarzeń | C10: Niezmienialny dziennik zdarzeń (kto, co, kiedy) | D10: 2, 49 | E10: =COUNTIF(W3_FUNKCJE_MVP!$L$6:$L$400,$A10) -> 2 | F10: WŁASNE na komponentach open source | G10: PostgreSQL (tabela tylko do dopisywania + łańcuch skrótów); immudb (Apache 2.0); Trillian / Sigstore Rekor (rejestr przejrzystości) | H10: Zasoby AuditEvent serwera FHIR | I10: Magazyn obiektów z blokadą zapisu (Object Lock): OVHcloud, Scaleway | J10: AWS S3 Object Lock (region UE); AWS QLDB — wycofany (nie wybierać) | K10: Łańcuch HMAC w bazie aplikacji (gotowe) | L10: PostgreSQL tylko do dopisywania + łańcuch HMAC + codzienny eksport do magazynu z blokadą zapisu w UE | M10: + codzienna kotwica skrótu poza naszą infrastrukturą | N10: + rejestr przejrzystości (Trillian/Rekor) dla audytu zewnętrznego | O10: PostgreSQL z dziennikiem tylko do dopisywania + magazyn plików z blokadą zapisu (2) | P10: BEZ ZMIAN | Q10: Zgodne z plikiem; gotowe w aplikacji; bez kosztów licencji. | R10: Format zdarzeń, weryfikacja łańcucha, widok „kto oglądał” dla pacjenta (A18.10) | S10: Wymóg audytora zewnętrznego → rejestr przejrzystości | T10: 5 | U10: Rozliczalność RODO (art. 5 ust. 2); retencja dziennika zgodna z dokumentacją medyczną | V10: Zaimplementowane: dziennik z łańcuchem HMAC, wyzwalacze blokujące zmiany, weryfikacja z CLI | W10: wiedza ogólna; niesprawdzone w sieci 10.2026
A11: W-06 | B11: Zgody i żądania RODO | C11: Platforma zgód i preferencji (zgody marketingowe, żądania RODO) | D11: 2 | E11: =COUNTIF(W3_FUNKCJE_MVP!$L$6:$L$400,$A11) -> 2 | F11: WŁASNE na komponentach open source | G11: Zasób Consent FHIR (nasz rejestr); Fides (Ethyca, Apache 2.0) — mapa danych i żądania | H11: — | I11: Didomi (FR); Usercentrics/Cookiebot (DE/DK) — tylko zgody marketingowe i cookies | J11: OneTrust | K11: Ekran zgody z wersją i datą (gotowe) | L11: Własny rejestr zgód (FHIR Consent z wersjami) + obsługa żądań RODO w panelu (eksport, usunięcie z potwierdzeniem) | M11: + Usercentrics albo Didomi wyłącznie dla strony www (cookies), jeśli będzie marketing w sieci | N11: Jak MLP + rejestr zgód per kraj | O11: nie bierzemy jako rdzenia (2) | P11: BEZ ZMIAN | Q11: Platformy zgód obsługują tylko marketing/cookies; zgody medyczne i udostępnienia muszą być w rekordzie. | R11: Wersje treści zgód, granularne wycofanie (A18.11), usunięcie z potwierdzeniem (A18.12) | S11: Marketing internetowy → platforma cookies | T11: 5 | U11: Art. 7 i 9 RODO; brak zgód „wiązanych” z usługą | V11: Zaimplementowane: zgody wersjonowane, eksport danych, usunięcie konta | W11: wiedza ogólna; niesprawdzone w sieci 10.2026
A12: W-07 | B12: Rekord zdrowia — serwer FHIR R4 | C12: Serwer rekordu zdrowia (standard FHIR) | D12: 5, 36 | E12: =COUNTIF(W3_FUNKCJE_MVP!$L$6:$L$400,$A12) -> 9 | F12: BIERZEMY OPEN SOURCE + nasza warstwa | G12: Medplum (Apache 2.0, TypeScript); HAPI FHIR 8.x (Apache 2.0, Java) | H12: Medplum hostowany — plan bezpłatny (rozwój); Aidbox — licencja deweloperska | I12: Aidbox (Health Samurai; licencja produkcyjna od ok. 600 USD) | J12: Medplum hostowany: Production 2 000 USD/mies., Premium 6 000 USD/mies.; Azure Health Data Services; Google Cloud Healthcare API; AWS HealthLake | K12: Lokalny magazyn FHIR aplikacji (gotowe) — 0 zł | L12: Medplum na własnej infrastrukturze w UE (adapter gotowy, ten sam język co aplikacja) | M12: Medplum w wysokiej dostępności (zarządzany PostgreSQL); opcjonalnie wsparcie Enterprise | N12: Medplum + eksport Bulk FHIR do magazynu analitycznego; zgodność z formatem EEHRxF (EHDS) | O12: Medplum (9) | P12: DOPRECYZOWANIE | Q12: Medplum zgodnie z plikiem, ale na własnej infrastrukturze w UE: hostowany Medplum kosztuje od 2 000 USD/mies. i nie ma potwierdzonego regionu UE. | R12: Profile danych PL, walidacja, wersje i historia, mapowania LOINC/UCUM, eksport (A2.6), reguły dostępu | S12: >1 mln zasobów lub wymagania EHDS → audyt wydajności i zgodności formatu | T12: 5 | U12: EHDS stosuje się od 26.03.2027 (systemy EHR — wymogi interoperacyjności falami 2029/2031) | V12: Zaimplementowane: repozytorium FHIR z trzema zapleczami (lokalne, Medplum przez SDK, dowolny FHIR R4); rezerwacja z If-Match | W12: sprawdzone 04.10.2026 [Z02, Z44, Z45, Z66]
A13: W-08 | B13: Chmura, baza i magazyn plików w UE | C13: Chmura i baza danych w UE | D13: 5 | E13: =COUNTIF(W3_FUNKCJE_MVP!$L$6:$L$400,$A13) -> 1 | F13: KUPUJEMY USŁUGĘ (przenośnie) | G13: Kubernetes/k3s, PostgreSQL, magazyn zgodny z S3 — uruchamialne u dowolnego dostawcy | H13: Kredyty startowe dostawców (warunki do sprawdzenia) | I13: OVHcloud (FR); Scaleway (FR); Hetzner (DE); STACKIT (DE) | J13: AWS (region UE; AWS European Sovereign Cloud w Brandenburgii od 15.01.2026); Microsoft Azure; Google Cloud | K13: Jeden serwer w UE — 50–200 zł/mies. | L13: AWS region UE (Frankfurt): zarządzany PostgreSQL, S3 z Object Lock, KMS — w jednym koncie z Bedrock; wszystko w kontenerach | M13: Jak MVP + kopia zapasowa u drugiego dostawcy z UE (OVHcloud) | N13: AWS European Sovereign Cloud albo OVHcloud dla klientów publicznych wymagających suwerenności | O13: AWS (region UE) (1) | P13: DOPRECYZOWANIE | Q13: AWS zgodnie z plikiem (jeden dostawca dla bazy, plików, kluczy i modeli językowych), ale z zasadą przenośności: kontenery, PostgreSQL, interfejs S3 — przeniesienie do OVHcloud bez przepisywania. | R13: Infrastruktura jako kod (OpenTofu), szyfrowanie kluczami własnymi, kopie w drugim regionie/dostawcy | S13: Wymóg klienta publicznego (suwerenność) → Sovereign Cloud/OVHcloud; koszt >30% przychodu → migracja | T13: 4 | U13: Umowa powierzenia, region UE, ISO 27001; transfer do USA — ocena (CLOUD Act) | V13: Gotowe obrazy Docker i docker-compose (Caddy); niezależne od dostawcy | W13: sprawdzone 04.10.2026 [Z29]
A14: W-09 | B14: Słowniki medyczne i terminologia | C14: Słowniki i standardy medyczne (nazwy badań, rozpoznań, leków, jednostek) | D14: 4, 33 | E14: =COUNTIF(W3_FUNKCJE_MVP!$L$6:$L$400,$A14) -> 2 | F14: DANE PUBLICZNE + nasza warstwa | G14: Snowstorm (serwer SNOMED, Apache 2.0); moduł terminologii Medplum/HAPI | H14: LOINC (po rejestracji), UCUM, ICD-10 (wersja polska), WHO ICD-11 API, NLM Clinical Tables | I14: — | J14: Ontoserver (CSIRO); SNOMED CT — licencja zależna od członkostwa kraju | K14: Mapowanie 20–50 badań na LOINC | L14: Tabela mapowań 150–300 badań (LOINC + UCUM + ICD-10 PL) + wyszukiwanie NLM/WHO | M14: Serwer terminologii (moduł Medplum albo Snowstorm) + ICD-11 | N14: + SNOMED CT, jeśli Polska udostępni licencję krajową | O14: LOINC, UCUM, ICD-10 (2) | P14: BEZ ZMIAN | Q14: Standardy bezpłatne; koszt to redakcja mapowań. | R14: Mapowania nazw z polskich laboratoriów na LOINC, konwersje jednostek (A11.4) | S14: Nowy kraj → słowniki krajowe | T14: 5 | U14: Licencje LOINC/ICD — atrybucja | V14: Zaimplementowane: NLM Clinical Tables, WHO ICD-11, kody LOINC w pomiarach | W14: wiedza ogólna; niesprawdzone w sieci 10.2026
A15: W-10 | B15: Odczyt dokumentów i wyników (OCR + parser) | C15: Usługa odczytu dokumentów (tekst i tabele ze zdjęcia albo PDF); Gotowy interfejs „wynik laboratoryjny → dane” | D15: 4, 25 | E15: =COUNTIF(W3_FUNKCJE_MVP!$L$6:$L$400,$A15) -> 5 | F15: HYBRYDA: kupiony silnik + własny parser polski | G15: Docling (MIT; PDF z warstwą tekstową); PaddleOCR (Apache 2.0); docTR (Apache 2.0); Tesseract 5 | H15: Skaner dokumentów systemu telefonu; odczyt warstwy tekstowej PDF (większość PDF z portali laboratoriów) — bez OCR | I15: Mistral OCR 4 (FR; 4 USD/1 000 stron, wsadowo 2 USD, z polami 5 USD; od 23.06.2026); Azure Document Intelligence (region UE) | J15: Google Document AI Enterprise OCR (1,5 USD/1 000 stron, region UE); AWS Textract | K15: Docling lokalnie (0 zł) + Mistral OCR na kilkudziesięciu dokumentach (kilka zł) | L15: Najpierw warstwa tekstowa PDF (0 zł), skany i zdjęcia → Mistral OCR 4; nasz parser 3–5 sieci laboratoriów; zatwierdzenie przez użytkownika | M15: Mistral OCR wsadowo + PaddleOCR/Docling u siebie dla prostych dokumentów | N15: Model otwarty na własnym GPU w UE, gdy wolumen przekroczy ok. 1 mln stron/mies. | O15: Google Document AI (4); nie bierzemy (1) | P15: ZMIANA | Q15: Google tańszy (1,5 vs 4 USD/1 000 stron), ale Mistral to podmiot z UE (brak transferu do USA), zwraca strukturę tabel, bloki i pewność odczytu; na MVP różnica to kilkanaście zł/mies. Google zostaje zamiennikiem nr 1. | R15: Polski parser wyników, mapowanie na LOINC/UCUM, kontrola zakresów, ekran zatwierdzenia (A2.3), oryginał w rekordzie | S15: >200 tys. stron/mies. → model u siebie; zmiana warunków przetwarzania → Google/Azure UE | T15: 5 | U15: Dokumenty = dane o zdrowiu: umowa powierzenia, brak trenowania na danych, przetwarzanie w UE | V15: Częściowo: wgrywanie dokumentów; brak odczytu treści | W15: sprawdzone 04.10.2026 [Z03, Z16]
A16: W-11 | B16: Modele językowe (brama modeli) | C16: Model językowy przez interfejs (silnik zdań, streszczeń i porządkowania tekstu); Rozpoznawanie posiłku ze zdjęcia | D16: 4, 9, 10, 11, 13 | E16: =COUNTIF(W3_FUNKCJE_MVP!$L$6:$L$400,$A16) -> 7 | F16: KUPUJEMY USŁUGĘ za własną bramą | G16: LiteLLM (MIT) — brama; modele otwarte: Bielik 11B v3 (Apache 2.0, polski), Mistral Small (Apache 2.0) | H16: Modele otwarte na własnym GPU (koszt sprzętu) | I16: Mistral (FR; Medium 3.5: 1,5 / 7,5 USD za 1 mln tokenów); Claude przez Amazon Bedrock z profilem eu.* (przetwarzanie tylko w UE) | J16: Claude API (Haiku 4.5: 1/5 USD; Sonnet 4.6: 3/15 USD za 1 mln tokenów); OpenAI (rezydencja UE +10%); Gemini (Vertex AI UE) | K16: Claude przez Bedrock (profil UE) — kilkadziesiąt zł | L16: Claude przez Amazon Bedrock (profil eu.*) za naszą bramą LiteLLM + Mistral jako drugi dostawca z UE (przełączanie) | M16: + Bielik v3 na własnym GPU w UE do zadań prostych (porządkowanie pól, klasyfikacja) | N16: Routing wielu modeli według zadania i kosztu; modele otwarte dla danych najbardziej wrażliwych | O16: Claude (Anthropic) (5); model językowy z obrazem przez interfejs (płatne tokeny) (2) | P16: DOPRECYZOWANIE | Q16: Claude przez Bedrock UE zgodnie z plikiem; brama i drugi dostawca usuwają zależność od jednego modelu i cennika. | R16: Brama: limity, maskowanie danych, logi zapytań, wersje poleceń, zbiory testowe PL, oznaczanie treści AI (A19.1), blokada interpretacji wyników | S16: Koszt tokenów > koszt GPU; klient wymaga „bez podmiotów z USA” → Mistral/Bielik | T16: 5 | U16: AI Act: przejrzystość (oznaczanie treści AI; dla systemów sprzed 2.08.2026 do 2.12.2026); granica MDR — model nie ocenia wyników | V16: Brak — świadomie (granica MDR w obecnej wersji) | W16: sprawdzone 04.10.2026 [Z05, Z31, Z64, Z65, Z09]
A17: W-12 | B17: Objaśnianie i interpretacja wyników (wyrób medyczny partnera) | C17: Interpretacja wyników laboratoryjnych (moduł z certyfikatem wyrobu medycznego) | D17: 6 | E17: =COUNTIF(W3_FUNKCJE_MVP!$L$6:$L$400,$A17) -> 2 | F17: POŚREDNICTWO PARTNERA (CE) + własny słownik | G17: — | H17: Słownik „co mierzy badanie” (redakcja własna, bez odniesienia do wyniku osoby) | I17: Labplus (PL, Wrocław; znak CE od 2023; 12 sieci laboratoriów, ok. 50% rynku badań w PL; API B2B) | J17: — | K17: Objaśnienia 20 badań (bez oceny wyniku) | L17: Słownik 200–300 haseł + Labplus jako moduł partnera dla interpretacji wyniku konkretnej osoby | M17: Labplus (pakiet „Dodatek med”) | N17: Labplus albo własny wyrób dopiero przy skali uzasadniającej certyfikację | O17: Labplus (LabTest Checker) (2) | P17: BEZ ZMIAN | Q17: Interpretacja wyniku konkretnej osoby jest funkcją wyrobu medycznego — tylko przez partnera z CE. | R17: Słownik, prezentacja wyniku partnera z oznaczeniem źródła, rozdzielenie od treści własnych | S17: Wolumen i przychód z pakietu → negocjacja albo własna certyfikacja | T17: 3 | U17: MDR reguła 11; AI Act — wyroby z AI: obowiązki od 2.08.2028 (omnibus) | V17: Świadomie brak interpretacji (COMPLIANCE.md §1) | W17: sprawdzone 04.10.2026 [Z10, Z09]; klasa wyrobu Labplus do potwierdzenia u producenta
... A73: W-99 | B73: Funkcja własna na wspólnych komponentach (W2) | C73: Nie ma gotowego rozwiązania do kupienia — funkcja powstaje u nas | D73: różne | E73: =COUNTIF(W3_FUNKCJE_MVP!$L$6:$L$400,$A73) -> 68 | F73: WŁASNE na komponentach z W2 | G73: Komponenty z arkusza W2 | H73: — | I73: — | J73: — | K73: Prosta wersja w aplikacji | L73: Budujemy w aplikacji Eternal na komponentach W2 | M73: Jak MVP | N73: Jak MVP | O73: — (brak ★ w pliku) | P73: BEZ ZMIAN | Q73: Plik: nie ma gotowego rozwiązania do kupienia — funkcja powstaje u nas. | R73: Cała funkcja | S73: Pojawi się gotowe rozwiązanie z CE / API → ponowna ocena | T73: 5 | U73: Sprawdzić granicę MDR dla każdej funkcji (uwagi w W3) | V73: Zob. kolumna uwag w W3 | W73: nie dotyczy

Sheet W2_KOMPONENTY
A1: W2 — KOMPONENTY TECHNICZNE WSPÓLNE (platforma pod wszystkimi funkcjami)
A2: Komponenty, z których budujemy funkcje własne (W-99) i warstwę kontroli nad usługami kupionymi. Zgodne z obecną aplikacją Eternal (app/).
A5: ID | B5: Warstwa | C5: Komponent | D5: Open source (licencja) | E5: Usługa / płatne | F5: ★ DEMO | G5: ★ MVP (2027) | H5: ★ MLP (2028) | I5: ★ FINAL | J5: Ryzyko licencji / dostawcy | K5: W aplikacji Eternal teraz | L5: Powiązane W- | M5: Źródła
A6: K-01 | B6: Klient | C6: Aplikacja mobilna (pacjent) | D6: React Native + Expo (MIT) | E6: Expo EAS: Free / Starter 19 / Production 199 USD/mies. | F6: PWA (gotowa) | G6: React Native/Expo — warunek HealthKit, Health Connect, biometrii i push | H6: Jak MVP | I6: Jak MVP | J6: Niski; alternatywy: Flutter, natywne Swift/Kotlin | K6: PWA gotowa | L6: W-14, W-19, W-90 | M6: Z55, Z56
A7: K-02 | B7: Klient | C7: Aplikacja web (pacjent + panel placówki) | D7: React 19 + Vite (MIT) | E7: — | F7: Gotowa | G7: Gotowa — rozbudowa | H7: Jak MVP | I7: Jak MVP | J7: Niski | K7: Gotowa | L7: — | M7: —
A8: K-03 | B8: Serwer | C8: API i logika | D8: Node.js 22 + Fastify 5 + TypeScript (MIT) | E8: — | F8: Gotowe | G8: Gotowe — rozbudowa | H8: Jak MVP | I8: Jak MVP | J8: Niski | K8: Gotowe | L8: — | M8: —
A9: K-04 | B9: Dane | C9: Baza danych | D9: PostgreSQL (licencja PostgreSQL); SQLite w Demo | E9: Zarządzany PostgreSQL (AWS RDS UE / OVHcloud) | F9: SQLite (gotowe) | G9: Zarządzany PostgreSQL w UE | H9: + replika i kopia u drugiego dostawcy | I9: Jak MLP | J9: Niski | K9: SQLite (node:sqlite) | L9: W-07, W-08 | M9: —
A10: K-05 | B10: Dane | C10: Magazyn plików | D10: Interfejs S3 | E10: AWS S3 UE z Object Lock; OVHcloud / Scaleway Object Storage | F10: Dysk serwera | G10: S3 w UE z szyfrowaniem i Object Lock dla dziennika | H10: + kopia u drugiego dostawcy | I10: Jak MLP | J10: Niski (standard S3) | K10: Pliki w bazie (binarne FHIR) | L10: W-05, W-08 | M10: —
A11: K-06 | B11: Serwer | C11: Kolejka zadań i przepływy | D11: Kolejka outbox w PostgreSQL; pg-boss (MIT); Temporal (MIT) | E11: Temporal Cloud | F11: Outbox (gotowe) | G11: Outbox + pg-boss | H11: Jak MVP | I11: Temporal dla długich procesów (Scribe, RPM) | J11: Niski | K11: Outbox gotowy | L11: W-19, W-24 | M11: —
A12: K-07 | B12: Serwer | C12: Pamięć podręczna | D12: Valkey (BSD) — zamiast Redis (zmiany licencji 2024/2025) | E12: Zarządzany Valkey/Redis | F12: Brak | G12: Valkey (Medplum wymaga Redis-zgodnego) | H12: Jak MVP | I12: Jak MVP | J12: Redis — zmiany licencji; Valkey bezpieczny | K12: Brak (cache w SQLite) | L12: W-07 | M12: wiedza ogólna
A13: K-08 | B13: AI | C13: Brama modeli | D13: LiteLLM (MIT) | E13: — | F13: Bezpośrednio Bedrock | G13: LiteLLM: Bedrock UE + Mistral | H13: + Bielik u siebie | I13: Routing per zadanie | J13: Niski | K13: Brak | L13: W-11, W-38 | M13: Z05, Z31
A14: K-09 | B14: Eksploatacja | C14: Obserwowalność i błędy | D14: OpenTelemetry; Grafana/Loki/Tempo (AGPL); GlitchTip (MIT) | E14: Grafana Cloud (UE); Sentry (licencja FSL) | F14: Logi serwera | G14: OpenTelemetry + Grafana u nas; maskowanie danych o zdrowiu w logach | H14: Jak MVP + alerty dyżurne | I14: Jak MLP | J14: AGPL — tylko użycie, bez modyfikacji | K14: Logi Fastify | L14: — | M14: wiedza ogólna
A15: K-10 | B15: Produkt | C15: Analityka produktu | D15: PostHog (MIT; chmura UE); Matomo (GPL) | E15: PostHog Cloud UE | F15: Brak | G15: Matomo albo PostHog bez danych o zdrowiu, bez reklam i bez profili marketingowych | H15: Jak MVP | I15: Jak MVP | J15: Zasady stałe: brak reklam i sprzedaży danych | K15: Brak | L15: — | M15: wiedza ogólna
A16: K-11 | B16: Eksploatacja | C16: CI/CD | D16: GitHub Actions (akcje przypięte do skrótu commita) | E16: Expo EAS Build | F16: Testy lokalne | G16: GitHub Actions: testy, typy, E2E, axe, SBOM, skany | H16: Jak MVP | I16: Jak MVP | J16: Łańcuch dostaw akcji (incydent Trivy 03.2026) | K16: Testy: 60 jednostkowych/API + 2 E2E | L16: W-36 | M16: Z12
... A22: K-17 | B22: Produkt | C22: Wyszukiwanie i wektory | D22: pgvector (PostgreSQL); OpenSearch (Apache 2.0) | E22: — | F22: — | G22: pgvector w tej samej bazie (asystent wiedzy) | H22: Jak MVP | I22: OpenSearch przy dużej skali | J22: Niski | K22: Brak | L22: W-13 | M22: —

Sheet W3_FUNKCJE_MVP
A1: W3 — KAŻDA FUNKCJA MVP Z PLIKU 11.1 → WYBRANE ROZWIĄZANIE
A2: 251 pozycji: funkcje z „Wydanie produktu” = MVP (Z1 kol. 15). Kolumny A–K z pliku 11.1; L = przypisanie; M–Q i S liczą się formułami z W1 (zmiana w W1 aktualizuje W3).
A3: Łączenie z plikiem 11.1: kolumna A (Kod) = Z1_KARTY_FUNKCJI_648, kolumna A. Kolumna R — uwagi dotyczące tylko tej funkcji.
A5: Kod | B5: Funkcja (nazwa z rejestru) | C5: Projekt | D5: Produkt | E5: Wydanie produktu (plik) | F5: Etap realny (plik) | G5: Nr funkcji zbiorczej | H5: Funkcja zbiorcza | I5: Rodzaj pozycji | J5: Zdolność w pliku 11.1 | K5: ★ w pliku 11.1 | L5: ID wyboru | M5: Zdolność / moduł (W1) | N5: Model budowy (W1) | O5: ★ MVP (W1) | P5: ★ MLP (W1) | Q5: Zmiana względem pliku (W1) | R5: Uwaga do tej funkcji | S5: Stan w aplikacji Eternal (W1)
A6: A23.1 | B6: Zgodność ze standardem dostępności | C6: P1 — Eternal App | D6: Eternal App Core | E6: MVP produktu (2027) | F6: MVP | G6: 33 | H6: Dostępność, język i region | I6: funkcja | J6: Narzędzia testów dostępności i audyt | K6: axe (Deque) i czytniki ekranu systemu | L6: W-33 | M6: =IFERROR(INDEX(W1_WYBOR!$B$6:$B$80,MATCH($L6,W1_WYBOR!$A$6:$A$80,0)),"") -> Dostępność — testy i audyt | N6: =IFERROR(INDEX(W1_WYBOR!$F$6:$F$80,MATCH($L6,W1_WYBOR!$A$6:$A$80,0)),"") -> OPEN SOURCE + audyt ludzki | O6: =IFERROR(INDEX(W1_WYBOR!$L$6:$L$80,MATCH($L6,W1_WYBOR!$A$6:$A$80,0)),"") -> axe w testach E2E + audyt ręczny przed wydaniem | P6: =IFERROR(INDEX(W1_WYBOR!$M$6:$M$80,MATCH($L6,W1_WYBOR!$A$6:$A$80,0)),"") -> Audyt zewnętrzny (5–15 tys. zł wg pliku) | Q6: =IFERROR(INDEX(W1_WYBOR!$P$6:$P$80,MATCH($L6,W1_WYBOR!$A$6:$A$80,0)),"") -> BEZ ZMIAN | S6: =IFERROR(INDEX(W1_WYBOR!$V$6:$V$80,MATCH($L6,W1_WYBOR!$A$6:$A$80,0)),"") -> Częściowo: semantyka, fokus, kontrast; brak axe w CI — do dodania
A7: A23.2 | B7: Tryb prostego języka | C7: P1 — Eternal App | D7: Eternal App Core | E7: MVP produktu (2027) | F7: MVP | G7: 33 | H7: Dostępność, język i region | I7: funkcja | J7: Nie ma gotowego rozwiązania do kupienia — funkcja powstaje u nas | K7: — | L7: W-99 | M7: =IFERROR(INDEX(W1_WYBOR!$B$6:$B$80,MATCH($L7,W1_WYBOR!$A$6:$A$80,0)),"") -> Funkcja własna na wspólnych komponentach (W2) | N7: =IFERROR(INDEX(W1_WYBOR!$F$6:$F$80,MATCH($L7,W1_WYBOR!$A$6:$A$80,0)),"") -> WŁASNE na komponentach z W2 | O7: =IFERROR(INDEX(W1_WYBOR!$L$6:$L$80,MATCH($L7,W1_WYBOR!$A$6:$A$80,0)),"") -> Budujemy w aplikacji Eternal na komponentach W2 | P7: =IFERROR(INDEX(W1_WYBOR!$M$6:$M$80,MATCH($L7,W1_WYBOR!$A$6:$A$80,0)),"") -> Jak MVP | Q7: =IFERROR(INDEX(W1_WYBOR!$P$6:$P$80,MATCH($L7,W1_WYBOR!$A$6:$A$80,0)),"") -> BEZ ZMIAN | S7: =IFERROR(INDEX(W1_WYBOR!$V$6:$V$80,MATCH($L7,W1_WYBOR!$A$6:$A$80,0)),"") -> Zob. kolumna uwag w W3
A8: A23.3 | B8: Duży kontrast i skalowanie | C8: P1 — Eternal App | D8: Eternal App Core | E8: MVP produktu (2027) | F8: MVP | G8: 33 | H8: Dostępność, język i region | I8: funkcja | J8: Funkcję daje ustawienia systemu telefonu — nie kupujemy jej | K8: Ustawienia systemu telefonu | L8: W-90 | M8: =IFERROR(INDEX(W1_WYBOR!$B$6:$B$80,MATCH($L8,W1_WYBOR!$A$6:$A$80,0)),"") -> Funkcja systemu telefonu, przeglądarki lub urządzenia (nie kupujemy) | N8: =IFERROR(INDEX(W1_WYBOR!$F$6:$F$80,MATCH($L8,W1_WYBOR!$A$6:$A$80,0)),"") -> SYSTEM | O8: =IFERROR(INDEX(W1_WYBOR!$L$6:$L$80,MATCH($L8,W1_WYBOR!$A$6:$A$80,0)),"") -> Funkcja systemu + nasza obsługa w aplikacji | P8: =IFERROR(INDEX(W1_WYBOR!$M$6:$M$80,MATCH($L8,W1_WYBOR!$A$6:$A$80,0)),"") -> Jak MVP | Q8: =IFERROR(INDEX(W1_WYBOR!$P$6:$P$80,MATCH($L8,W1_WYBOR!$A$6:$A$80,0)),"") -> BEZ ZMIAN | S8: =IFERROR(INDEX(W1_WYBOR!$V$6:$V$80,MATCH($L8,W1_WYBOR!$A$6:$A$80,0)),"") -> Częściowo (PWA); pełny dostęp w aplikacji mobilnej
A9: A23.4 | B9: Obsługa czytnikiem ekranu i głosem | C9: P1 — Eternal App | D9: Eternal App Core | E9: MVP produktu (2027) | F9: MVP | G9: 33 | H9: Dostępność, język i region | I9: funkcja | J9: Funkcję daje czytniki ekranu systemu telefonu — nie kupujemy jej | K9: Czytniki ekranu systemu telefonu | L9: W-90 | M9: =IFERROR(INDEX(W1_WYBOR!$B$6:$B$80,MATCH($L9,W1_WYBOR!$A$6:$A$80,0)),"") -> Funkcja systemu telefonu, przeglądarki lub urządzenia (nie kupujemy) | N9: =IFERROR(INDEX(W1_WYBOR!$F$6:$F$80,MATCH($L9,W1_WYBOR!$A$6:$A$80,0)),"") -> SYSTEM | O9: =IFERROR(INDEX(W1_WYBOR!$L$6:$L$80,MATCH($L9,W1_WYBOR!$A$6:$A$80,0)),"") -> Funkcja systemu + nasza obsługa w aplikacji | P9: =IFERROR(INDEX(W1_WYBOR!$M$6:$M$80,MATCH($L9,W1_WYBOR!$A$6:$A$80,0)),"") -> Jak MVP | Q9: =IFERROR(INDEX(W1_WYBOR!$P$6:$P$80,MATCH($L9,W1_WYBOR!$A$6:$A$80,0)),"") -> BEZ ZMIAN | S9: =IFERROR(INDEX(W1_WYBOR!$V$6:$V$80,MATCH($L9,W1_WYBOR!$A$6:$A$80,0)),"") -> Częściowo (PWA); pełny dostęp w aplikacji mobilnej
A10: A3.1 | B10: Dashboard główny | C10: P1 — Eternal App | D10: Eternal App Core | E10: MVP produktu (2027) | F10: MVP | G10: 7 | H10: Pulpit, wykresy i oś czasu | I10: funkcja | J10: Biblioteki wykresów i panele analityczne | K10: ECharts i Victory Native | L10: W-21 | M10: =IFERROR(INDEX(W1_WYBOR!$B$6:$B$80,MATCH($L10,W1_WYBOR!$A$6:$A$80,0)),"") -> Pulpit i wykresy | N10: =IFERROR(INDEX(W1_WYBOR!$F$6:$F$80,MATCH($L10,W1_WYBOR!$A$6:$A$80,0)),"") -> OPEN SOURCE w aplikacji | O10: =IFERROR(INDEX(W1_WYBOR!$L$6:$L$80,MATCH($L10,W1_WYBOR!$A$6:$A$80,0)),"") -> ECharts (web) + Victory Native (mobile); proste trendy na własnym SVG | P10: =IFERROR(INDEX(W1_WYBOR!$M$6:$M$80,MATCH($L10,W1_WYBOR!$A$6:$A$80,0)),"") -> Jak MVP; Superset dla zespołu | Q10: =IFERROR(INDEX(W1_WYBOR!$P$6:$P$80,MATCH($L10,W1_WYBOR!$A$6:$A$80,0)),"") -> BEZ ZMIAN | S10: =IFERROR(INDEX(W1_WYBOR!$V$6:$V$80,MATCH($L10,W1_WYBOR!$A$6:$A$80,0)),"") -> Zaimplementowane: wykres trendu SVG (responsywny, dostępny)
A11: A3.2 | B11: Wykresy trendów | C11: P1 — Eternal App | D11: Eternal App Core | E11: MVP produktu (2027) | F11: MVP | G11: 7 | H11: Pulpit, wykresy i oś czasu | I11: funkcja | J11: Biblioteki wykresów i panele analityczne | K11: ECharts i Victory Native | L11: W-21 | M11: =IFERROR(INDEX(W1_WYBOR!$B$6:$B$80,MATCH($L11,W1_WYBOR!$A$6:$A$80,0)),"") -> Pulpit i wykresy | N11: =IFERROR(INDEX(W1_WYBOR!$F$6:$F$80,MATCH($L11,W1_WYBOR!$A$6:$A$80,0)),"") -> OPEN SOURCE w aplikacji | O11: =IFERROR(INDEX(W1_WYBOR!$L$6:$L$80,MATCH($L11,W1_WYBOR!$A$6:$A$80,0)),"") -> ECharts (web) + Victory Native (mobile); proste trendy na własnym SVG | P11: =IFERROR(INDEX(W1_WYBOR!$M$6:$M$80,MATCH($L11,W1_WYBOR!$A$6:$A$80,0)),"") -> Jak MVP; Superset dla zespołu | Q11: =IFERROR(INDEX(W1_WYBOR!$P$6:$P$80,MATCH($L11,W1_WYBOR!$A$6:$A$80,0)),"") -> BEZ ZMIAN | S11: =IFERROR(INDEX(W1_WYBOR!$V$6:$V$80,MATCH($L11,W1_WYBOR!$A$6:$A$80,0)),"") -> Zaimplementowane: wykres trendu SVG (responsywny, dostępny)
A12: A3.4 | B12: System powiadomień | C12: P1 — Eternal App | D12: Eternal App Core | E12: MVP produktu (2027) | F12: MVP | G12: 8 | H12: Powiadomienia, przypomnienia i eskalacja | I12: funkcja | J12: Silnik powiadomień (push, e-mail, SMS, kolejność kanałów) | K12: własna kolejka na bezpłatnych usługach systemowych Apple (APNs) i Google (FCM) + e-mail przez Amazon SES + bramka SMS | L12: W-19 | M12: =IFERROR(INDEX(W1_WYBOR!$B$6:$B$80,MATCH($L12,W1_WYBOR!$A$6:$A$80,0)),"") -> Powiadomienia i przypomnienia | N12: =IFERROR(INDEX(W1_WYBOR!$F$6:$F$80,MATCH($L12,W1_WYBOR!$A$6:$A$80,0)),"") -> WŁASNA KOLEJKA na bezpłatnych kanałach | O12: =IFERROR(INDEX(W1_WYBOR!$L$6:$L$80,MATCH($L12,W1_WYBOR!$A$6:$A$80,0)),"") -> Nasza kolejka (gotowa) + APNs/FCM/Web Push + Amazon SES (region UE) + SMSAPI | P12: =IFERROR(INDEX(W1_WYBOR!$M$6:$M$80,MATCH($L12,W1_WYBOR!$A$6:$A$80,0)),"") -> Novu na naszym serwerze, gdy rośnie liczba kanałów, szablonów i preferencji | Q12: =IFERROR(INDEX(W1_WYBOR!$P$6:$P$80,MATCH($L12,W1_WYBOR!$A$6:$A$80,0)),"") -> BEZ ZMIAN | S12: =IFERROR(INDEX(W1_WYBOR!$V$6:$V$80,MATCH($L12,W1_WYBOR!$A$6:$A$80,0)),"") -> Zaimplementowane: kolejka, Web Push, SMTP, SMS, preferencje, przypomnienia o wizytach
A13: A2.1 | B13: OCR wyników laboratoryjnych | C13: P1 — Eternal App | D13: Eternal App Core | E13: MVP produktu (2027) | F13: MVP | G13: 4 | H13: Odczyt dokumentów i wyników (zdjęcie, PDF, parser) | I13: funkcja | J13: Usługa odczytu dokumentów (tekst i tabele ze zdjęcia albo PDF) | K13: Google Document AI | L13: W-10 | M13: =IFERROR(INDEX(W1_WYBOR!$B$6:$B$80,MATCH($L13,W1_WYBOR!$A$6:$A$80,0)),"") -> Odczyt dokumentów i wyników (OCR + parser) | N13: =IFERROR(INDEX(W1_WYBOR!$F$6:$F$80,MATCH($L13,W1_WYBOR!$A$6:$A$80,0)),"") -> HYBRYDA: kupiony silnik + własny parser polski | O13: =IFERROR(INDEX(W1_WYBOR!$L$6:$L$80,MATCH($L13,W1_WYBOR!$A$6:$A$80,0)),"") -> Najpierw warstwa tekstowa PDF (0 zł), skany i zdjęcia → Mistral OCR 4; nasz parser 3–5 sieci laboratoriów; zatwierdzenie przez użytkownika | P13: =IFERROR(INDEX(W1_WYBOR!$M$6:$M$80,MATCH($L13,W1_WYBOR!$A$6:$A$80,0)),"") -> Mistral OCR wsadowo + PaddleOCR/Docling u siebie dla prostych dokumentów | Q13: =IFERROR(INDEX(W1_WYBOR!$P$6:$P$80,MATCH($L13,W1_WYBOR!$A$6:$A$80,0)),"") -> ZMIANA | R13: Najpierw warstwa tekstowa PDF (0 zł), skany → Mistral OCR 4. | S13: =IFERROR(INDEX(W1_WYBOR!$V$6:$V$80,MATCH($L13,W1_WYBOR!$A$6:$A$80,0)),"") -> Częściowo: wgrywanie dokumentów; brak odczytu treści
A14: A2.2 | B14: Parsowanie do FHIR Observation | C14: P1 — Eternal App | D14: Eternal App Core | E14: MVP produktu (2027) | F14: MVP | G14: 4 | H14: Odczyt dokumentów i wyników (zdjęcie, PDF, parser) | I14: funkcja | J14: Model językowy przez interfejs (silnik zdań, streszczeń i porządkowania tekstu) | K14: Claude (Anthropic) | L14: W-11 | M14: =IFERROR(INDEX(W1_WYBOR!$B$6:$B$80,MATCH($L14,W1_WYBOR!$A$6:$A$80,0)),"") -> Modele językowe (brama modeli) | N14: =IFERROR(INDEX(W1_WYBOR!$F$6:$F$80,MATCH($L14,W1_WYBOR!$A$6:$A$80,0)),"") -> KUPUJEMY USŁUGĘ za własną bramą | O14: =IFERROR(INDEX(W1_WYBOR!$L$6:$L$80,MATCH($L14,W1_WYBOR!$A$6:$A$80,0)),"") -> Claude przez Amazon Bedrock (profil eu.*) za naszą bramą LiteLLM + Mistral jako drugi dostawca z UE (przełączanie) | P14: =IFERROR(INDEX(W1_WYBOR!$M$6:$M$80,MATCH($L14,W1_WYBOR!$A$6:$A$80,0)),"") -> + Bielik v3 na własnym GPU w UE do zadań prostych (porządkowanie pól, klasyfikacja) | Q14: =IFERROR(INDEX(W1_WYBOR!$P$6:$P$80,MATCH($L14,W1_WYBOR!$A$6:$A$80,0)),"") -> DOPRECYZOWANIE | R14: Porządkowanie pól przez bramę modeli (Claude/Bedrock UE) + walidacja kodów LOINC. | S14: =IFERROR(INDEX(W1_WYBOR!$V$6:$V$80,MATCH($L14,W1_WYBOR!$A$6:$A$80,0)),"") -> Brak — świadomie (granica MDR w obecnej wersji)
A15: A2.3 | B15: Walidacja i korekta OCR | C15: P1 — Eternal App | D15: Eternal App Core | E15: MVP produktu (2027) | F15: MVP | G15: 4 | H15: Odczyt dokumentów i wyników (zdjęcie, PDF, parser) | I15: funkcja | J15: Nie ma gotowego rozwiązania do kupienia — funkcja powstaje u nas | K15: — | L15: W-99 | M15: =IFERROR(INDEX(W1_WYBOR!$B$6:$B$80,MATCH($L15,W1_WYBOR!$A$6:$A$80,0)),"") -> Funkcja własna na wspólnych komponentach (W2) | N15: =IFERROR(INDEX(W1_WYBOR!$F$6:$F$80,MATCH($L15,W1_WYBOR!$A$6:$A$80,0)),"") -> WŁASNE na komponentach z W2 | O15: =IFERROR(INDEX(W1_WYBOR!$L$6:$L$80,MATCH($L15,W1_WYBOR!$A$6:$A$80,0)),"") -> Budujemy w aplikacji Eternal na komponentach W2 | P15: =IFERROR(INDEX(W1_WYBOR!$M$6:$M$80,MATCH($L15,W1_WYBOR!$A$6:$A$80,0)),"") -> Jak MVP | Q15: =IFERROR(INDEX(W1_WYBOR!$P$6:$P$80,MATCH($L15,W1_WYBOR!$A$6:$A$80,0)),"") -> BEZ ZMIAN | S15: =IFERROR(INDEX(W1_WYBOR!$V$6:$V$80,MATCH($L15,W1_WYBOR!$A$6:$A$80,0)),"") -> Zob. kolumna uwag w W3
A16: A2.4 | B16: Tłumaczenie wyników na język naturalny | C16: P1 — Eternal App | D16: Eternal App Core | E16: MVP produktu (2027) | F16: MVP | G16: 6 | H16: Objaśnianie wyników prostym językiem | I16: funkcja | J16: Interpretacja wyników laboratoryjnych (moduł z certyfikatem wyrobu medycznego) | K16: Labplus (LabTest Checker) | L16: W-12 | M16: =IFERROR(INDEX(W1_WYBOR!$B$6:$B$80,MATCH($L16,W1_WYBOR!$A$6:$A$80,0)),"") -> Objaśnianie i interpretacja wyników (wyrób medyczny partnera) | N16: =IFERROR(INDEX(W1_WYBOR!$F$6:$F$80,MATCH($L16,W1_WYBOR!$A$6:$A$80,0)),"") -> POŚREDNICTWO PARTNERA (CE) + własny słownik | O16: =IFERROR(INDEX(W1_WYBOR!$L$6:$L$80,MATCH($L16,W1_WYBOR!$A$6:$A$80,0)),"") -> Słownik 200–300 haseł + Labplus jako moduł partnera dla interpretacji wyniku konkretnej osoby | P16: =IFERROR(INDEX(W1_WYBOR!$M$6:$M$80,MATCH($L16,W1_WYBOR!$A$6:$A$80,0)),"") -> Labplus (pakiet „Dodatek med”) | Q16: =IFERROR(INDEX(W1_WYBOR!$P$6:$P$80,MATCH($L16,W1_WYBOR!$A$6:$A$80,0)),"") -> BEZ ZMIAN | R16: Objaśnienie wyniku konkretnej osoby = wyrób medyczny → tylko Labplus (CE); własny słownik ogólny. | S16: =IFERROR(INDEX(W1_WYBOR!$V$6:$V$80,MATCH($L16,W1_WYBOR!$A$6:$A$80,0)),"") -> Świadomie brak interpretacji (COMPLIANCE.md §1)
A17: A2.5 | B17: Historia badań z wersjonowaniem | C17: P1 — Eternal App | D17: Eternal App Core | E17: MVP produktu (2027) | F17: MVP | G17: 5 | H17: Rekord zdrowia i historia (portfel danych) | I17: funkcja | J17: Serwer rekordu zdrowia (standard FHIR) | K17: Medplum | L17: W-07 | M17: =IFERROR(INDEX(W1_WYBOR!$B$6:$B$80,MATCH($L17,W1_WYBOR!$A$6:$A$80,0)),"") -> Rekord zdrowia — serwer FHIR R4 | N17: =IFERROR(INDEX(W1_WYBOR!$F$6:$F$80,MATCH($L17,W1_WYBOR!$A$6:$A$80,0)),"") -> BIERZEMY OPEN SOURCE + nasza warstwa | O17: =IFERROR(INDEX(W1_WYBOR!$L$6:$L$80,MATCH($L17,W1_WYBOR!$A$6:$A$80,0)),"") -> Medplum na własnej infrastrukturze w UE (adapter gotowy, ten sam język co aplikacja) | P17: =IFERROR(INDEX(W1_WYBOR!$M$6:$M$80,MATCH($L17,W1_WYBOR!$A$6:$A$80,0)),"") -> Medplum w wysokiej dostępności (zarządzany PostgreSQL); opcjonalnie wsparcie Enterprise | Q17: =IFERROR(INDEX(W1_WYBOR!$P$6:$P$80,MATCH($L17,W1_WYBOR!$A$6:$A$80,0)),"") -> DOPRECYZOWANIE | S17: =IFERROR(INDEX(W1_WYBOR!$V$6:$V$80,MATCH($L17,W1_WYBOR!$A$6:$A$80,0)),"") -> Zaimplementowane: repozytorium FHIR z trzema zapleczami (lokalne, Medplum przez SDK, dowolny FHIR R4); rezerwacja z If-Match
A18: A2.6 | B18: Eksport CSV/PDF/FHIR Bundle | C18: P1 — Eternal App | D18: Eternal App Core | E18: MVP produktu (2027) | F18: MVP | G18: 5 | H18: Rekord zdrowia i historia (portfel danych) | I18: funkcja | J18: Serwer rekordu zdrowia (standard FHIR) | K18: Medplum | L18: W-07 | M18: =IFERROR(INDEX(W1_WYBOR!$B$6:$B$80,MATCH($L18,W1_WYBOR!$A$6:$A$80,0)),"") -> Rekord zdrowia — serwer FHIR R4 | N18: =IFERROR(INDEX(W1_WYBOR!$F$6:$F$80,MATCH($L18,W1_WYBOR!$A$6:$A$80,0)),"") -> BIERZEMY OPEN SOURCE + nasza warstwa | O18: =IFERROR(INDEX(W1_WYBOR!$L$6:$L$80,MATCH($L18,W1_WYBOR!$A$6:$A$80,0)),"") -> Medplum na własnej infrastrukturze w UE (adapter gotowy, ten sam język co aplikacja) | P18: =IFERROR(INDEX(W1_WYBOR!$M$6:$M$80,MATCH($L18,W1_WYBOR!$A$6:$A$80,0)),"") -> Medplum w wysokiej dostępności (zarządzany PostgreSQL); opcjonalnie wsparcie Enterprise | Q18: =IFERROR(INDEX(W1_WYBOR!$P$6:$P$80,MATCH($L18,W1_WYBOR!$A$6:$A$80,0)),"") -> DOPRECYZOWANIE | S18: =IFERROR(INDEX(W1_WYBOR!$V$6:$V$80,MATCH($L18,W1_WYBOR!$A$6:$A$80,0)),"") -> Zaimplementowane: repozytorium FHIR z trzema zapleczami (lokalne, Medplum przez SDK, dowolny FHIR R4); rezerwacja z If-Match
A19: A2.7 | B19: OCR recept i zaświadczeń | C19: P1 — Eternal App | D19: Eternal App Core | E19: MVP produktu (2027) | F19: MVP | G19: 4 | H19: Odczyt dokumentów i wyników (zdjęcie, PDF, parser) | I19: funkcja | J19: Usługa odczytu dokumentów (tekst i tabele ze zdjęcia albo PDF) | K19: Google Document AI | L19: W-10 | M19: =IFERROR(INDEX(W1_WYBOR!$B$6:$B$80,MATCH($L19,W1_WYBOR!$A$6:$A$80,0)),"") -> Odczyt dokumentów i wyników (OCR + parser) | N19: =IFERROR(INDEX(W1_WYBOR!$F$6:$F$80,MATCH($L19,W1_WYBOR!$A$6:$A$80,0)),"") -> HYBRYDA: kupiony silnik + własny parser polski | O19: =IFERROR(INDEX(W1_WYBOR!$L$6:$L$80,MATCH($L19,W1_WYBOR!$A$6:$A$80,0)),"") -> Najpierw warstwa tekstowa PDF (0 zł), skany i zdjęcia → Mistral OCR 4; nasz parser 3–5 sieci laboratoriów; zatwierdzenie przez użytkownika | P19: =IFERROR(INDEX(W1_WYBOR!$M$6:$M$80,MATCH($L19,W1_WYBOR!$A$6:$A$80,0)),"") -> Mistral OCR wsadowo + PaddleOCR/Docling u siebie dla prostych dokumentów | Q19: =IFERROR(INDEX(W1_WYBOR!$P$6:$P$80,MATCH($L19,W1_WYBOR!$A$6:$A$80,0)),"") -> ZMIANA | R19: Jak A2.1. | S19: =IFERROR(INDEX(W1_WYBOR!$V$6:$V$80,MATCH($L19,W1_WYBOR!$A$6:$A$80,0)),"") -> Częściowo: wgrywanie dokumentów; brak odczytu treści
A20: A2.8 | B20: Integracja z P1 | C20: P1 — Eternal App | D20: Eternal App Core | E20: MVP produktu (2027) | F20: MVP | G20: 18 | H20: Brama do e-zdrowia (e-recepta, e-skierowanie, P1) | I20: funkcja | J20: Systemy gabinetowe z gotową integracją z krajową platformą e-zdrowia (e-recepta, e-skierowanie) | K20: MyDr | L20: W-28 | M20: =IFERROR(INDEX(W1_WYBOR!$B$6:$B$80,MATCH($L20,W1_WYBOR!$A$6:$A$80,0)),"") -> Brama e-zdrowia (P1: e-recepta, e-skierowanie) | N20: =IFERROR(INDEX(W1_WYBOR!$F$6:$F$80,MATCH($L20,W1_WYBOR!$A$6:$A$80,0)),"") -> POŚREDNICTWO przez system gabinetowy placówki | O20: =IFERROR(INDEX(W1_WYBOR!$L$6:$L$80,MATCH($L20,W1_WYBOR!$A$6:$A$80,0)),"") -> E-recepty i e-skierowania wystawia lekarz w systemie gabinetowym placówki; Eternal pokazuje status i dokumenty; adaptery do API systemów, które je mają | P20: =IFERROR(INDEX(W1_WYBOR!$M$6:$M$80,MATCH($L20,W1_WYBOR!$A$6:$A$80,0)),"") -> Konektor P1 (np. Pentacomp) dla placówek, gdy Eternal Doctor staje się systemem placówki | Q20: =IFERROR(INDEX(W1_WYBOR!$P$6:$P$80,MATCH($L20,W1_WYBOR!$A$6:$A$80,0)),"") -> DOPRECYZOWANIE | R20: Dokumenty z P1 przez system gabinetowy placówki albo pobrane przez pacjenta z IKP; Eternal nie łączy się z P1 w MVP. | S20: =IFERROR(INDEX(W1_WYBOR!$V$6:$V$80,MATCH($L20,W1_WYBOR!$A$6:$A$80,0)),"") -> Brak (świadomie — opisane w INTEGRATIONS.md)
A21: F3.1 | B21: Skan dokumentu z aparatu (CamScanner-like UX) | C21: P1 — Eternal App | D21: Eternal App Core | E21: MVP produktu (2027) | F21: MVP | G21: 4 | H21: Odczyt dokumentów i wyników (zdjęcie, PDF, parser) | I21: funkcja | J21: Funkcję daje system telefonu (skaner dokumentów) — nie kupujemy jej | K21: System telefonu (skaner dokumentów) | L21: W-90 | M21: =IFERROR(INDEX(W1_WYBOR!$B$6:$B$80,MATCH($L21,W1_WYBOR!$A$6:$A$80,0)),"") -> Funkcja systemu telefonu, przeglądarki lub urządzenia (nie kupujemy) | N21: =IFERROR(INDEX(W1_WYBOR!$F$6:$F$80,MATCH($L21,W1_WYBOR!$A$6:$A$80,0)),"") -> SYSTEM | O21: =IFERROR(INDEX(W1_WYBOR!$L$6:$L$80,MATCH($L21,W1_WYBOR!$A$6:$A$80,0)),"") -> Funkcja systemu + nasza obsługa w aplikacji | P21: =IFERROR(INDEX(W1_WYBOR!$M$6:$M$80,MATCH($L21,W1_WYBOR!$A$6:$A$80,0)),"") -> Jak MVP | Q21: =IFERROR(INDEX(W1_WYBOR!$P$6:$P$80,MATCH($L21,W1_WYBOR!$A$6:$A$80,0)),"") -> BEZ ZMIAN | S21: =IFERROR(INDEX(W1_WYBOR!$V$6:$V$80,MATCH($L21,W1_WYBOR!$A$6:$A$80,0)),"") -> Częściowo (PWA); pełny dostęp w aplikacji mobilnej
A22: F3.2 | B22: PDF upload z Google Drive / Files | C22: P1 — Eternal App | D22: Eternal App Core | E22: MVP produktu (2027) | F22: MVP | G22: 4 | H22: Odczyt dokumentów i wyników (zdjęcie, PDF, parser) | I22: funkcja | J22: Nie ma gotowego rozwiązania do kupienia — funkcja powstaje u nas | K22: — | L22: W-99 | M22: =IFERROR(INDEX(W1_WYBOR!$B$6:$B$80,MATCH($L22,W1_WYBOR!$A$6:$A$80,0)),"") -> Funkcja własna na wspólnych komponentach (W2) | N22: =IFERROR(INDEX(W1_WYBOR!$F$6:$F$80,MATCH($L22,W1_WYBOR!$A$6:$A$80,0)),"") -> WŁASNE na komponentach z W2 | O22: =IFERROR(INDEX(W1_WYBOR!$L$6:$L$80,MATCH($L22,W1_WYBOR!$A$6:$A$80,0)),"") -> Budujemy w aplikacji Eternal na komponentach W2 | P22: =IFERROR(INDEX(W1_WYBOR!$M$6:$M$80,MATCH($L22,W1_WYBOR!$A$6:$A$80,0)),"") -> Jak MVP | Q22: =IFERROR(INDEX(W1_WYBOR!$P$6:$P$80,MATCH($L22,W1_WYBOR!$A$6:$A$80,0)),"") -> BEZ ZMIAN | S22: =IFERROR(INDEX(W1_WYBOR!$V$6:$V$80,MATCH($L22,W1_WYBOR!$A$6:$A$80,0)),"") -> Zob. kolumna uwag w W3
A23: F3.3 | B23: OCR z Tesseract 5 + polish trained model | C23: P1 — Eternal App | D23: Eternal App Core | E23: MVP produktu (2027) | F23: MVP | G23: 4 | H23: Odczyt dokumentów i wyników (zdjęcie, PDF, parser) | I23: powtórzenie funkcji A2.1 | J23: Usługa odczytu dokumentów (tekst i tabele ze zdjęcia albo PDF) | K23: Google Document AI | L23: W-10 | M23: =IFERROR(INDEX(W1_WYBOR!$B$6:$B$80,MATCH($L23,W1_WYBOR!$A$6:$A$80,0)),"") -> Odczyt dokumentów i wyników (OCR + parser) | N23: =IFERROR(INDEX(W1_WYBOR!$F$6:$F$80,MATCH($L23,W1_WYBOR!$A$6:$A$80,0)),"") -> HYBRYDA: kupiony silnik + własny parser polski | O23: =IFERROR(INDEX(W1_WYBOR!$L$6:$L$80,MATCH($L23,W1_WYBOR!$A$6:$A$80,0)),"") -> Najpierw warstwa tekstowa PDF (0 zł), skany i zdjęcia → Mistral OCR 4; nasz parser 3–5 sieci laboratoriów; zatwierdzenie przez użytkownika | P23: =IFERROR(INDEX(W1_WYBOR!$M$6:$M$80,MATCH($L23,W1_WYBOR!$A$6:$A$80,0)),"") -> Mistral OCR wsadowo + PaddleOCR/Docling u siebie dla prostych dokumentów | Q23: =IFERROR(INDEX(W1_WYBOR!$P$6:$P$80,MATCH($L23,W1_WYBOR!$A$6:$A$80,0)),"") -> ZMIANA | R23: Tesseract z pliku zastąpiony: warstwa tekstowa PDF → Mistral OCR 4; Tesseract/PaddleOCR jako zapas lokalny. | S23: =IFERROR(INDEX(W1_WYBOR!$V$6:$V$80,MATCH($L23,W1_WYBOR!$A$6:$A$80,0)),"") -> Częściowo: wgrywanie dokumentów; brak odczytu treści
A24: F3.4 | B24: Parser polskich wyników lab (Synevo, Diagnostyka, ALAB) | C24: P1 — Eternal App | D24: Eternal App Core | E24: MVP produktu (2027) | F24: MVP | G24: 4 | H24: Odczyt dokumentów i wyników (zdjęcie, PDF, parser) | I24: funkcja | J24: Gotowy interfejs „wynik laboratoryjny → dane” | K24: nie bierzemy | L24: W-10 | M24: =IFERROR(INDEX(W1_WYBOR!$B$6:$B$80,MATCH($L24,W1_WYBOR!$A$6:$A$80,0)),"") -> Odczyt dokumentów i wyników (OCR + parser) | N24: =IFERROR(INDEX(W1_WYBOR!$F$6:$F$80,MATCH($L24,W1_WYBOR!$A$6:$A$80,0)),"") -> HYBRYDA: kupiony silnik + własny parser polski | O24: =IFERROR(INDEX(W1_WYBOR!$L$6:$L$80,MATCH($L24,W1_WYBOR!$A$6:$A$80,0)),"") -> Najpierw warstwa tekstowa PDF (0 zł), skany i zdjęcia → Mistral OCR 4; nasz parser 3–5 sieci laboratoriów; zatwierdzenie przez użytkownika | P24: =IFERROR(INDEX(W1_WYBOR!$M$6:$M$80,MATCH($L24,W1_WYBOR!$A$6:$A$80,0)),"") -> Mistral OCR wsadowo + PaddleOCR/Docling u siebie dla prostych dokumentów | Q24: =IFERROR(INDEX(W1_WYBOR!$P$6:$P$80,MATCH($L24,W1_WYBOR!$A$6:$A$80,0)),"") -> ZMIANA | R24: Parser własny — rdzeń przewagi (3–5 sieci laboratoriów na MVP). | S24: =IFERROR(INDEX(W1_WYBOR!$V$6:$V$80,MATCH($L24,W1_WYBOR!$A$6:$A$80,0)),"") -> Częściowo: wgrywanie dokumentów; brak odczytu treści
A25: F3.5 | B25: Mapowanie do LOINC code (standard medyczny) | C25: P1 — Eternal App | D25: Eternal App Core | E25: MVP produktu (2027) | F25: MVP | G25: 4 | H25: Odczyt dokumentów i wyników (zdjęcie, PDF, parser) | I25: funkcja | J25: Słowniki i standardy medyczne (nazwy badań, rozpoznań, leków, jednostek) | K25: LOINC, UCUM, ICD-10 | L25: W-09 | M25: =IFERROR(INDEX(W1_WYBOR!$B$6:$B$80,MATCH($L25,W1_WYBOR!$A$6:$A$80,0)),"") -> Słowniki medyczne i terminologia | N25: =IFERROR(INDEX(W1_WYBOR!$F$6:$F$80,MATCH($L25,W1_WYBOR!$A$6:$A$80,0)),"") -> DANE PUBLICZNE + nasza warstwa | O25: =IFERROR(INDEX(W1_WYBOR!$L$6:$L$80,MATCH($L25,W1_WYBOR!$A$6:$A$80,0)),"") -> Tabela mapowań 150–300 badań (LOINC + UCUM + ICD-10 PL) + wyszukiwanie NLM/WHO | P25: =IFERROR(INDEX(W1_WYBOR!$M$6:$M$80,MATCH($L25,W1_WYBOR!$A$6:$A$80,0)),"") -> Serwer terminologii (moduł Medplum albo Snowstorm) + ICD-11 | Q25: =IFERROR(INDEX(W1_WYBOR!$P$6:$P$80,MATCH($L25,W1_WYBOR!$A$6:$A$80,0)),"") -> BEZ ZMIAN | S25: =IFERROR(INDEX(W1_WYBOR!$V$6:$V$80,MATCH($L25,W1_WYBOR!$A$6:$A$80,0)),"") -> Zaimplementowane: NLM Clinical Tables, WHO ICD-11, kody LOINC w pomiarach
A26: F3.6 | B26: Alert gdy parametr poza norma | C26: P1 — Eternal App | D26: Eternal App Core | E26: MVP produktu (2027) | F26: MVP | G26: 8 | H26: Powiadomienia, przypomnienia i eskalacja | I26: funkcja | J26: Nie ma gotowego rozwiązania do kupienia — funkcja powstaje u nas | K26: — | L26: W-99 | M26: =IFERROR(INDEX(W1_WYBOR!$B$6:$B$80,MATCH($L26,W1_WYBOR!$A$6:$A$80,0)),"") -> Funkcja własna na wspólnych komponentach (W2) | N26: =IFERROR(INDEX(W1_WYBOR!$F$6:$F$80,MATCH($L26,W1_WYBOR!$A$6:$A$80,0)),"") -> WŁASNE na komponentach z W2 | O26: =IFERROR(INDEX(W1_WYBOR!$L$6:$L$80,MATCH($L26,W1_WYBOR!$A$6:$A$80,0)),"") -> Budujemy w aplikacji Eternal na komponentach W2 | P26: =IFERROR(INDEX(W1_WYBOR!$M$6:$M$80,MATCH($L26,W1_WYBOR!$A$6:$A$80,0)),"") -> Jak MVP | Q26: =IFERROR(INDEX(W1_WYBOR!$P$6:$P$80,MATCH($L26,W1_WYBOR!$A$6:$A$80,0)),"") -> BEZ ZMIAN | R26: Tylko oznaczenie zakresu referencyjnego podanego przez laboratorium; własne alerty = funkcja wyrobu (MDR) → partner z CE. | S26: =IFERROR(INDEX(W1_WYBOR!$V$6:$V$80,MATCH($L26,W1_WYBOR!$A$6:$A$80,0)),"") -> Zob. kolumna uwag w W3
A27: F3.8 | B27: Recepta z P1 (NFZ Online API) | C27: P1 — Eternal App | D27: Eternal App Core | E27: MVP produktu (2027) | F27: MVP-2 | G27: 18 | H27: Brama do e-zdrowia (e-recepta, e-skierowanie, P1) | I27: powtórzenie funkcji A5.6 | J27: Systemy gabinetowe z gotową integracją z krajową platformą e-zdrowia (e-recepta, e-skierowanie) | K27: MyDr | L27: W-28 | M27: =IFERROR(INDEX(W1_WYBOR!$B$6:$B$80,MATCH($L27,W1_WYBOR!$A$6:$A$80,0)),"") -> Brama e-zdrowia (P1: e-recepta, e-skierowanie) | N27: =IFERROR(INDEX(W1_WYBOR!$F$6:$F$80,MATCH($L27,W1_WYBOR!$A$6:$A$80,0)),"") -> POŚREDNICTWO przez system gabinetowy placówki | O27: =IFERROR(INDEX(W1_WYBOR!$L$6:$L$80,MATCH($L27,W1_WYBOR!$A$6:$A$80,0)),"") -> E-recepty i e-skierowania wystawia lekarz w systemie gabinetowym placówki; Eternal pokazuje status i dokumenty; adaptery do API systemów, które je mają | P27: =IFERROR(INDEX(W1_WYBOR!$M$6:$M$80,MATCH($L27,W1_WYBOR!$A$6:$A$80,0)),"") -> Konektor P1 (np. Pentacomp) dla placówek, gdy Eternal Doctor staje się systemem placówki | Q27: =IFERROR(INDEX(W1_WYBOR!$P$6:$P$80,MATCH($L27,W1_WYBOR!$A$6:$A$80,0)),"") -> DOPRECYZOWANIE | R27: Recepty wystawia system gabinetowy placówki; Eternal pokazuje status/kod. | S27: =IFERROR(INDEX(W1_WYBOR!$V$6:$V$80,MATCH($L27,W1_WYBOR!$A$6:$A$80,0)),"") -> Brak (świadomie — opisane w INTEGRATIONS.md)
A28: F3.9 | B28: Karta wypisowa szpitalna | C28: P1 — Eternal App | D28: Eternal App Core | E28: MVP produktu (2027) | F28: MVP | G28: 4 | H28: Odczyt dokumentów i wyników (zdjęcie, PDF, parser) | I28: funkcja | J28: Model językowy przez interfejs (silnik zdań, streszczeń i porządkowania tekstu) | K28: Claude (Anthropic) | L28: W-11 | M28: =IFERROR(INDEX(W1_WYBOR!$B$6:$B$80,MATCH($L28,W1_WYBOR!$A$6:$A$80,0)),"") -> Modele językowe (brama modeli) | N28: =IFERROR(INDEX(W1_WYBOR!$F$6:$F$80,MATCH($L28,W1_WYBOR!$A$6:$A$80,0)),"") -> KUPUJEMY USŁUGĘ za własną bramą | O28: =IFERROR(INDEX(W1_WYBOR!$L$6:$L$80,MATCH($L28,W1_WYBOR!$A$6:$A$80,0)),"") -> Claude przez Amazon Bedrock (profil eu.*) za naszą bramą LiteLLM + Mistral jako drugi dostawca z UE (przełączanie) | P28: =IFERROR(INDEX(W1_WYBOR!$M$6:$M$80,MATCH($L28,W1_WYBOR!$A$6:$A$80,0)),"") -> + Bielik v3 na własnym GPU w UE do zadań prostych (porządkowanie pól, klasyfikacja) | Q28: =IFERROR(INDEX(W1_WYBOR!$P$6:$P$80,MATCH($L28,W1_WYBOR!$A$6:$A$80,0)),"") -> DOPRECYZOWANIE | R28: Streszczenie karty wypisowej — tylko fakty z dokumentu, oznaczone jako AI. | S28: =IFERROR(INDEX(W1_WYBOR!$V$6:$V$80,MATCH($L28,W1_WYBOR!$A$6:$A$80,0)),"") -> Brak — świadomie (granica MDR w obecnej wersji)
A29: F3.19 | B29: Audio recording wizyt + transkrypcja (Whisper) + auto-SBAR | C29: P1 — Eternal App | D29: Eternal App Core | E29: MVP produktu (2027) | F29: MVP-1 | G29: 19 | H29: Scribe — nagranie, transkrypcja, notatka | I29: funkcja | J29: Gotowy produkt albo interfejs Scribe (nagranie wizyty → uporządkowana notatka) | K29: Corti | L29: W-24 | M29: =IFERROR(INDEX(W1_WYBOR!$B$6:$B$80,MATCH($L29,W1_WYBOR!$A$6:$A$80,0)),"") -> Scribe — notatka z wizyty | N29: =IFERROR(INDEX(W1_WYBOR!$F$6:$F$80,MATCH($L29,W1_WYBOR!$A$6:$A$80,0)),"") -> WŁASNY PRZEBIEG na kupionych silnikach | O29: =IFERROR(INDEX(W1_WYBOR!$L$6:$L$80,MATCH($L29,W1_WYBOR!$A$6:$A$80,0)),"") -> Przebieg własny: ElevenLabs Scribe (UE) + Claude (Bedrock UE) + polskie szablony; obowiązkowe zatwierdzenie lekarza | P29: =IFERROR(INDEX(W1_WYBOR!$M$6:$M$80,MATCH($L29,W1_WYBOR!$A$6:$A$80,0)),"") -> Ponowny przegląd gotowych scribe — wybór, jeśli dodadzą polski z dokumentacją zgodności | Q29: =IFERROR(INDEX(W1_WYBOR!$P$6:$P$80,MATCH($L29,W1_WYBOR!$A$6:$A$80,0)),"") -> ZMIANA | R29: Corti nie obsługuje polskiego → przebieg własny: ElevenLabs Scribe (UE) + Claude (Bedrock UE) + zatwierdzenie lekarza. | S29: =IFERROR(INDEX(W1_WYBOR!$V$6:$V$80,MATCH($L29,W1_WYBOR!$A$6:$A$80,0)),"") -> Brak
A30: F1.1 | B30: Rejestracja przez email/Apple/Google (OAuth 2.0) | C30: P1 — Eternal App | D30: Eternal App Core | E30: MVP produktu (2027) | F30: MVP | G30: 1 | H30: Konto, logowanie i tożsamość | I30: funkcja | J30: Serwer albo usługa tożsamości (konto, logowanie, sesje, drugi składnik, klucze dostępu) | K30: Amazon Cognito | L30: W-01 | M30: =IFERROR(INDEX(W1_WYBOR!$B$6:$B$80,MATCH($L30,W1_WYBOR!$A$6:$A$80,0)),"") -> Tożsamość, logowanie i sesje | N30: =IFERROR(INDEX(W1_WYBOR!$F$6:$F$80,MATCH($L30,W1_WYBOR!$A$6:$A$80,0)),"") -> BIERZEMY OPEN SOURCE + nasza warstwa | O30: =IFERROR(INDEX(W1_WYBOR!$L$6:$L$80,MATCH($L30,W1_WYBOR!$A$6:$A$80,0)),"") -> Keycloak w naszej chmurze UE jako dostawca OIDC: klucze dostępu (WebAuthn/FIDO2), logowanie Apple/Google, TOTP, link e-mail, sesje i urządzenia; PIN i biometria lokalnie w aplikacji mobilnej | P30: =IFERROR(INDEX(W1_WYBOR!$M$6:$M$80,MATCH($L30,W1_WYBOR!$A$6:$A$80,0)),"") -> Keycloak w klastrze (wysoka dostępność); organizacje = placówki; SMS jako drugi składnik tylko awaryjnie | Q30: =IFERROR(INDEX(W1_WYBOR!$P$6:$P$80,MATCH($L30,W1_WYBOR!$A$6:$A$80,0)),"") -> ZMIANA | R30: Keycloak: e-mail, Apple, Google (OIDC). | S30: =IFERROR(INDEX(W1_WYBOR!$V$6:$V$80,MATCH($L30,W1_WYBOR!$A$6:$A$80,0)),"") -> Zaimplementowane własne logowanie (scrypt, TOTP z ochroną przed powtórzeniem, sesje, CSRF, HIBP); do podłączenia jako klient OIDC
